Workbook

Sheet 「Rating」的副本
A1: NBA ID | B1: Season | C1: Player | D1: Team(s) | E1: Current Team | F1: PLAYER_LAST_NAME | G1: PLAYER_FIRST_NAME | H1: Primary_Position | I1: Second_Position | J1: Overall | K1: Layup | L1: ST Dunk | M1: Dunk | N1: Close | O1: Mid | P1: 3PT | Q1: FT | R1: PHook | S1: PFade | T1: PostC | U1: Foul | V1: SHOTIQ | W1: Ball | X1: SPD/BALL | Y1: Hands | Z1: Pass | AA1: Pass IQ | AB1: Vision | AC1: OCNST | AD1: ID | AE1: PD | AF1: STL | AG1: BLK | AH1: OREB | AI1: DREB | AJ1: HelpDIQ | AK1: PSPER | AL1: DCNST | AM1: SPEED | AN1: Agility | AO1: STR | AP1: VERT | AQ1: STAM | AR1: INTNGBL | AS1: HSTL | AT1: Aerial Wizard | AU1: Ankle Assassin | AV1: Bail Out | AW1: Boxout Beast | AX1: Break Starter | AY1: Brick Wall | AZ1: Challenger | BA1: Deadeye | BB1: Dimer | BC1: Float Game | BD1: Glove | BE1: Handles for Days | BF1: High Flying Denier | BG1: Hook Specialist | BH1: Immovable Enforcer | BI1: Interceptor | BJ1: Layup Mixmaster | BK1: Lightning Launch | BL1: Limitless Range | BM1: Mini Marksman | BN1: Off Ball Pest | BO1: On-Ball Menace | BP1: Paint Patroller | BQ1: Paint Prodigy | BR1: Physical Finisher | BS1: Pick Dodger | BT1: Pogo Stick | BU1: Posterizer | BV1: Post Fade Phenom | BW1: Post Lockdown | BX1: Post Powerhouse | BY1: Post Up Poet | BZ1: Rebound Chaser | CA1: Rise Up | CB1: Set Shot Specialist | CC1: Shifty Shooter | CD1: Slippery Off Ball | CE1: Strong Handle | CF1: Unpluckable | CG1: Versatile Visionary
A2: 708 | B2: 2013-14 | C2: Kevin Garnett | D2: BRK | F2: Garnett | G2: Kevin | K2: 63.683084 | L2: 65.653398 | M2: 60.466228 | N2: 62.78233 | O2: 82.280105 | P2: 25 | Q2: 80.977463 | R2: 60.983865 | S2: 67.131681 | T2: 78.352189 | U2: 52.801133 | V2: 62.266032 | W2: 48.732129 | X2: 51.142707 | Y2: 87.223579 | Z2: 58.909773 | AA2: 66.712565 | AB2: 69.139411 | AC2: 42.022859 | AD2: 82.496095 | AE2: 57.518774 | AF2: 72.282555 | AG2: 75.884649 | AH2: 67.869322 | AI2: 93.808541 | AJ2: 91.052076 | AK2: 60.094766 | AL2: 94.106695 | AM2: 64.076194 | AN2: 56.881228 | AO2: 81.214396 | AP2: 72.430638 | AQ2: 87.449288 | AR2: 70 | AS2: 82.500446 | AT2: 0 | AU2: 0 | AV2: 0 | AW2: 0 | AX2: 0 | AY2: 0 | AZ2: 0 | BA2: 0 | BB2: 1 | BC2: 0 | BD2: 1 | BE2: 0 | BF2: 1 | BG2: 1 | BH2: 0 | BI2: 0 | BJ2: 0 | BK2: 0 | BL2: 0 | BM2: 0 | BN2: 0 | BO2: 0 | BP2: 1 | BQ2: 0 | BR2: 0 | BS2: 0 | BT2: 2 | BU2: 0 | BV2: 1 | BW2: 2 | BX2: 2 | BY2: 2 | BZ2: 3 | CA2: 0 | CB2: 0 | CC2: 0 | CD2: 0 | CE2: 0 | CF2: 1 | CG2: 0
A3: 708 | B3: 2014-15 | C3: Kevin Garnett | D3: BRK/MIN | F3: Garnett | G3: Kevin | K3: 69.07861 | L3: 47.179969 | M3: 47.649174 | N3: 69.376127 | O3: 90.001596 | P3: 25.10232 | Q3: 80.018006 | R3: 45.662686 | S3: 69.421969 | T3: 71.925968 | U3: 60.322343 | V3: 75.792738 | W3: 59.152335 | X3: 53.094222 | Y3: 91.314011 | Z3: 71.841931 | AA3: 71.448294 | AB3: 70.864656 | AC3: 65.694707 | AD3: 76.228688 | AE3: 62.439437 | AF3: 79.557099 | AG3: 56.578337 | AH3: 60.026844 | AI3: 94.037139 | AJ3: 84.054829 | AK3: 72.370345 | AL3: 93.93091 | AM3: 64.204587 | AN3: 57.638271 | AO3: 79.057258 | AP3: 65.135978 | AQ3: 87.256141 | AR3: 89.889813 | AS3: 78.012753 | AT3: 0 | AU3: 0 | AV3: 0 | AW3: 0 | AX3: 1 | AY3: 0 | AZ3: 0 | BA3: 2 | BB3: 2 | BC3: 0 | BD3: 2 | BE3: 0 | BF3: 0 | BG3: 0 | BH3: 0 | BI3: 0 | BJ3: 0 | BK3: 0 | BL3: 0 | BM3: 0 | BN3: 1 | BO3: 0 | BP3: 0 | BQ3: 0 | BR3: 0 | BS3: 0 | BT3: 1 | BU3: 0 | BV3: 1 | BW3: 1 | BX3: 1 | BY3: 1 | BZ3: 3 | CA3: 0 | CB3: 0 | CC3: 1 | CD3: 0 | CE3: 0 | CF3: 0 | CG3: 0
A4: 708 | B4: 2015-16 | C4: Kevin Garnett | D4: MIN | F4: Garnett | G4: Kevin | K4: 65.245256 | L4: 36.917468 | M4: 39.973194 | N4: 72.714043 | O4: 78.912202 | P4: 25 | Q4: 71.428967 | R4: 54.029298 | S4: 60.401338 | T4: 81.382569 | U4: 50.802472 | V4: 72.519086 | W4: 50.322581 | X4: 63.263558 | Y4: 85.821352 | Z4: 72.847313 | AA4: 68.852828 | AB4: 72.306198 | AC4: 56.331211 | AD4: 74.302093 | AE4: 72.39095 | AF4: 76.962799 | AG4: 51.939786 | AH4: 43.304433 | AI4: 82.169645 | AJ4: 80.549085 | AK4: 66.317656 | AL4: 95.177029 | AM4: 73.330075 | AN4: 63.721873 | AO4: 77.251158 | AP4: 61.599357 | AQ4: 85.25335 | AR4: 87.233702 | AS4: 70.861056 | AT4: 0 | AU4: 0 | AV4: 0 | AW4: 0 | AX4: 1 | AY4: 0 | AZ4: 0 | BA4: 0 | BB4: 0 | BC4: 0 | BD4: 0 | BE4: 0 | BF4: 0 | BG4: 0 | BH4: 0 | BI4: 0 | BJ4: 0 | BK4: 0 | BL4: 0 | BM4: 0 | BN4: 0 | BO4: 0 | BP4: 0 | BQ4: 1 | BR4: 0 | BS4: 0 | BT4: 0 | BU4: 0 | BV4: 1 | BW4: 1 | BX4: 1 | BY4: 2 | BZ4: 2 | CA4: 0 | CB4: 0 | CC4: 0 | CD4: 0 | CE4: 0 | CF4: 1 | CG4: 0
A5: 951 | B5: 2013-14 | C5: Ray Allen | D5: MIA | F5: Allen | G5: Ray | K5: 72.091306 | L5: 38.271424 | M5: 61.524491 | N5: 83.162382 | O5: 87.119534 | P5: 81.060657 | Q5: 88.938747 | R5: 46.92544 | S5: 52.995264 | T5: 61.468664 | U5: 56.629812 | V5: 92.681862 | W5: 74.706818 | X5: 40.401921 | Y5: 81.063784 | Z5: 71.242141 | AA5: 73.601045 | AB5: 72.273419 | AC5: 91.66036 | AD5: 32.830801 | AE5: 67.419503 | AF5: 61.007501 | AG5: 35.313091 | AH5: 39.003664 | AI5: 62.199031 | AJ5: 61.217801 | AK5: 56.929036 | AL5: 58.091207 | AM5: 58.131638 | AN5: 70.000047 | AO5: 64.530353 | AP5: 72.741946 | AQ5: 89.332651 | AR5: 81.122799 | AS5: 58.533628 | AT5: 0 | AU5: 1 | AV5: 0 | AW5: 0 | AX5: 1 | AY5: 0 | AZ5: 0 | BA5: 1 | BB5: 2 | BC5: 1 | BD5: 0 | BE5: 0 | BF5: 0 | BG5: 0 | BH5: 0 | BI5: 0 | BJ5: 0 | BK5: 0 | BL5: 0 | BM5: 0 | BN5: 1 | BO5: 0 | BP5: 0 | BQ5: 1 | BR5: 1 | BS5: 0 | BT5: 0 | BU5: 0 | BV5: 0 | BW5: 0 | BX5: 0 | BY5: 0 | BZ5: 0 | CA5: 0 | CB5: 2 | CC5: 0 | CD5: 1 | CE5: 2 | CF5: 1 | CG5: 0
A6: 959 | B6: 2013-14 | C6: Steve Nash | D6: LAL | F6: Nash | G6: Steve | K6: 72.800199 | L6: 29.752627 | M6: 63.434647 | N6: 75.35222 | O6: 82.888305 | P6: 77.67143 | Q6: 87.420813 | R6: 54.471756 | S6: 67.168378 | T6: 56.894376 | U6: 62.244484 | V6: 67.442573 | W6: 86.633604 | X6: 85.696732 | Y6: 98 | Z6: 90.341151 | AA6: 94.662285 | AB6: 91.832258 | AC6: 72.350904 | AD6: 34.828639 | AE6: 75.907955 | AF6: 53.616335 | AG6: 39.260242 | AH6: 34.523672 | AI6: 48.554622 | AJ6: 67.623104 | AK6: 52.7195 | AL6: 57.159793 | AM6: 83.913904 | AN6: 89.498035 | AO6: 40.513381 | AP6: 49.182345 | AQ6: 88.123577 | AR6: 63.018391 | AS6: 60.311615 | AT6: 0 | AU6: 2 | AV6: 1 | AW6: 0 | AX6: 3 | AY6: 0 | AZ6: 0 | BA6: 0 | BB6: 3 | BC6: 1 | BD6: 0 | BE6: 2 | BF6: 0 | BG6: 0 | BH6: 0 | BI6: 0 | BJ6: 0 | BK6: 3 | BL6: 0 | BM6: 1 | BN6: 2 | BO6: 1 | BP6: 0 | BQ6: 1 | BR6: 0 | BS6: 0 | BT6: 0 | BU6: 0 | BV6: 1 | BW6: 0 | BX6: 0 | BY6: 0 | BZ6: 0 | CA6: 0 | CB6: 0 | CC6: 0 | CD6: 2 | CE6: 0 | CF6: 2 | CG6: 0

Sheet 「Finishing」的副本
A1: NBA ID | B1: Season | C1: Player | D1: Layup Rating | F1: Layup | G1: Finishing Talent | H1: Rim Shot Creation | I1: Drives Per 75 Possessions | J1: Rim Shot Making | K1: Rim Shot Making Efficiency | L1: Paint Shooting Talent | M1: Paint Shooting Talent | N1: Paint Shooting Talent | O1: Rim Makes Consistency | P1: DRIVES | Q1: DRIVE_FGM | R1: Stable Rim FG% | S1: Contact Finish Rate | T1: Rim Attempt Consistency | U1: less_than_5ft_FGM | V1: Rim FG% | W1: Drive Foul Drawn Rate | X1: less_than_5ft_FG_PCT | Y1: Standing Dunk Rating | AA1: Standing Dunk | AB1: Standing_dunk_PG | AC1: Standing_dunk_FGM | AD1: dunkScore_total | AE1: dunkScore_average | AF1: dunkScore_max | AG1: Putback Frequency% | AH1: Putback Scoring Impact Per 75 Possessions | AI1: Stable Putback Points Per 75 | AJ1: Offensive Rebound | AK1: Offensive Rebounding Crashing Skill | AL1: PLAYER_HEIGHT_INCHES | AM1: Putback per Offensive Rebound | AN1: Driving Dunk Rating | AP1: Driving Dunk | AQ1: Drving Dunk_PG | AR1: Drving Dunk_FGM | AS1: Rim Shot Creation | AT1: dunkScore_max | AU1: dunkScore_total | AV1: dunkScore_average | AW1: jumpSubscore_average | AX1: powerSubscore_average | AY1: styleSubscore_average | AZ1: hangTime_average | BA1: takeoffDistance_average | BB1: DRIVES | BC1: DRIVE_FGM | BD1: Post Hook Rating | BF1: Post Hook | BG1: Hook_Shot_FGM | BH1: Hook_Shot_PG | BI1: Hook_Shot_FG% | BJ1: Post Up Shot Making | BK1: Post Up Impact Per 75 Possessions | BL1: POST_TOUCHES | BM1: Post Up Impact Per 75 Possessions | BN1: Stable Post Up PPP | BO1: Post Fade | BQ1: Post Fade | BR1: Fadeway_Shot_FGM | BS1: Fadeway_Shot_PG | BT1: Post Up Shot Making | BU1: Fadeway_Shot_FG% | BV1: Post Up Frequency% | BW1: Post Up Impact Per 75 Possessions | BX1: Stable Post Up PPP | BY1: Post Control | CA1: Post Control | CB1: POST_TOUCHES | CC1: Post Up Frequency% | CD1: Post Up Impact Per 75 Possessions | CE1: Post Up Shot Making | CF1: Stable Post Up PPP | CG1: PTS_PER_POST_TOUCH | CH1: Post Up Shot Quality | CI1: Post Up Draw Foul Rate | CJ1: Draw Foul | CL1: Draw Foul | CM1: FTA_per100 | CN1: FTA | CO1: Fouls Drawn / 75 | CP1: Stable Fouls Drawn Per 75 | CQ1: Stable Shooting Fouls Drawn Per 75 | CR1: Stable Non Shooting Fouls Drawn Per 75 | CS1: Stable FTA Per 75 | CT1: Drive Foul Drawn Rate | CU1: Isolation Foul Drawn Rate | CV1: Post Up Draw Foul Rate | CW1: Hands | CY1: Hands | CZ1: Playmaking Talent | DA1: Touches Per 75 | DB1: TOUCHES
A2: 708 | B2: 2013-14 | C2: Kevin Garnett | D2: =IF(E2 <= PERCENTILE(E:E, 0.25), 25 + (E2 - MIN(E:E)) * (66 - 25) / (PERCENTILE(E:E, 0.25) - MIN(E:E)), IF(E2 <= PERCENTILE(E:E, 0.5), 66 + (E2 - PERCENTILE(E:E, 0.25)) * (73 - 66) / (PERCENTILE(E:E, 0.5) - PERCENTILE(E:E, 0.25)), IF(E2 <= PERCENTILE(E:E, 0.75), 73 + (E2 - PERCENTILE(E:E, 0.5)) * (80 - 73) / (PERCENTILE(E:E, 0.75) - PERCENTILE(E:E, 0.5)), IF(E2 <= PERCENTILE(E:E, 0.85), 80 + (E2 - PERCENTILE(E:E, 0.75)) * (84.45 - 80) / (PERCENTILE(E:E, 0.85) - PERCENTILE(E:E, 0.75)), IF(E2 <= PERCENTILE(E:E, 0.92), 84.45 + (E2 - PERCENTILE(E:E, 0.85)) * (89 - 84.45) / (PERCENTILE(E:E, 0.92) - PERCENTILE(E:E, 0.85)), IF(E2 <= PERCENTILE(E:E, 0.96), 89 + (E2 - PERCENTILE(E:E, 0.92)) * (94 - 89) / (PERCENTILE(E:E, 0.96) - PERCENTILE(E:E, 0.92)), IF(E2 <= PERCENTILE(E:E, 0.99), 94 + (E2 - PERCENTILE(E:E, 0.96)) * (98 - 94) / (PERCENTILE(E:E, 0.99) - PERCENTILE(E:E, 0.96)), 98 + (E2 - PERCENTILE(E:E, 0.99)) * (100 - 98) / (PERCENTILE(E:E, 1) - PERCENTILE(E:E, 0.99)) ))))))) -> 25 | E2: =(F2-MEDIAN(F:F))/STDEV(F:F) -> -1.2928819 | F2: =iferror(if(ISBLANK(G2:Q2),-0.5,AVERAGE(G2:Q2))*0.8+iferror(AVERAGE(R2:U2, 0)*0.15, 0)+iferror(AVERAGE(V2:X2, 0)*0.5, 0), -1) -> -0.85350788 | G2: -1.0095531 | H2: -1.0846131 | I2: -1.0530508 | J2: -1.0196089 | K2: -1.4463518 | L2: -0.65712904 | M2: -0.65712904 | N2: -0.65712904 | O2: 0.17962185 | P2: -0.81314307 | Q2: -0.70369549 | R2: -1.1155262 | S2: -0.45190796 | T2: 0.40596452 | U2: -0.53888537 | V2: -0.24619975 | W2: -0.91312151 | X2: -0.069801808 | Y2: =IF(Z2 <= PERCENTILE(Z:Z, 0.25), 25 + (Z2 - MIN(Z:Z)) * (30 - 25) / (PERCENTILE(Z:Z, 0.25) - MIN(Z:Z)), IF(Z2 <= PERCENTILE(Z:Z, 0.4), 30 + (Z2 - PERCENTILE(Z:Z, 0.25)) * (40 - 30) / (PERCENTILE(Z:Z, 0.4) - PERCENTILE(Z:Z, 0.25)), IF(Z2 <= PERCENTILE(Z:Z, 0.55), 40 + (Z2 - PERCENTILE(Z:Z, 0.4)) * (50 - 40) / (PERCENTILE(Z:Z, 0.55) - PERCENTILE(Z:Z, 0.4)), IF(Z2 <= PERCENTILE(Z:Z, 0.7), 50 + (Z2 - PERCENTILE(Z:Z, 0.55)) * (65 - 50) / (PERCENTILE(Z:Z, 0.7) - PERCENTILE(Z:Z, 0.55)), IF(Z2 <= PERCENTILE(Z:Z, 0.85), 65 + (Z2 - PERCENTILE(Z:Z, 0.7)) * (80 - 65) / (PERCENTILE(Z:Z, 0.85) - PERCENTILE(Z:Z, 0.7)), IF(Z2 <= PERCENTILE(Z:Z, 0.95), 80 + (Z2 - PERCENTILE(Z:Z, 0.85)) * (90 - 80) / (PERCENTILE(Z:Z, 0.95) - PERCENTILE(Z:Z, 0.85)), IF(Z2 <= PERCENTILE(Z:Z, 0.99), 90 + (Z2 - PERCENTILE(Z:Z, 0.95)) * (96 - 90) / (PERCENTILE(Z:Z, 0.99) - PERCENTILE(Z:Z, 0.95)), 96 + (Z2 - PERCENTILE(Z:Z, 0.99)) * (100 - 96) / (PERCENTILE(Z:Z, 1) - PERCENTILE(Z:Z, 0.99)) ))))))) -> 100 | Z2: =(AA2-MEDIAN(AA:AA))/STDEV(AA:AA) -> 2.0219107 | AA2: =IFERROR(AVERAGE(AB2:AD2)*0.7+AVERAGE(AE2:AL2)*0.25+AM2*0.05, -1) -> 0.012628823 | AB2: 0.031148611 | AC2: -0.00060220972 | AG2: 0.15826429 | AH2: -1.1667744 | AI2: -0.0038992041 | AJ2: 0.31441664 | AK2: -1.1854735 | AL2: 1.2898873 | AM2: 0.53340068 | AN2: =IF(AO2 <= PERCENTILE(AO:AO, 0.15), 25 + (AO2 - MIN(AO:AO)) * (41 - 25) / (PERCENTILE(AO:AO, 0.15) - MIN(AO:AO)), IF(AO2 <= PERCENTILE(AO:AO, 0.3), 41 + (AO2 - PERCENTILE(AO:AO, 0.15)) * (55 - 41) / (PERCENTILE(AO:AO, 0.3) - PERCENTILE(AO:AO, 0.15)), IF(AO2 <= PERCENTILE(AO:AO, 0.5), 55 + (AO2 - PERCENTILE(AO:AO, 0.3)) * (65 - 55) / (PERCENTILE(AO:AO, 0.5) - PERCENTILE(AO:AO, 0.3)), IF(AO2 <= PERCENTILE(AO:AO, 0.7), 65 + (AO2 - PERCENTILE(AO:AO, 0.5)) * (75 - 65) / (PERCENTILE(AO:AO, 0.7) - PERCENTILE(AO:AO, 0.5)), IF(AO2 <= PERCENTILE(AO:AO, 0.85), 75 + (AO2 - PERCENTILE(AO:AO, 0.7)) * (80 - 75) / (PERCENTILE(AO:AO, 0.85) - PERCENTILE(AO:AO, 0.7)), IF(AO2 <= PERCENTILE(AO:AO, 0.95), 80 + (AO2 - PERCENTILE(AO:AO, 0.85)) * (90 - 80) / (PERCENTILE(AO:AO, 0.95) - PERCENTILE(AO:AO, 0.85)), 90 + (AO2 - PERCENTILE(AO:AO, 0.95)) * (100 - 90) / (PERCENTILE(AO:AO, 1) - PERCENTILE(AO:AO, 0.95)) )))))) -> 65 | AO2: =(AP2-MEDIAN(AP:AP))/STDEV(AP:AP) -> 0 | AP2: =IFERROR(AQ2*0.4+AVERAGE(AR2:AU2)*0.45+AVERAGE(AV2:BC2)*0.15, -1) -> -0.39159398 | AQ2: -0.041478275 | AR2: -0.07863974 | AS2: -1.0846131 | BB2: -0.80963423 | BC2: -0.70064283 | BD2: =IF(BE2 <= PERCENTILE(BE:BE, 0.05), 25 + (BE2 - MIN(BE:BE)) * (26 - 25) / (PERCENTILE(BE:BE, 0.05) - MIN(BE:BE)), IF(BE2 <= PERCENTILE(BE:BE, 0.15), 26 + (BE2 - PERCENTILE(BE:BE, 0.05)) * (28 - 26) / (PERCENTILE(BE:BE, 0.15) - PERCENTILE(BE:BE, 0.05)), IF(BE2 <= PERCENTILE(BE:BE, 0.25), 28 + (BE2 - PERCENTILE(BE:BE, 0.15)) * (35 - 28) / (PERCENTILE(BE:BE, 0.25) - PERCENTILE(BE:BE, 0.15)), IF(BE2 <= PERCENTILE(BE:BE, 0.4), 35 + (BE2 - PERCENTILE(BE:BE, 0.25)) * (44 - 35) / (PERCENTILE(BE:BE, 0.4) - PERCENTILE(BE:BE, 0.25)), IF(BE2 <= PERCENTILE(BE:BE, 0.6), 44 + (BE2 - PERCENTILE(BE:BE, 0.4)) * (56 - 44) / (PERCENTILE(BE:BE, 0.6) - PERCENTILE(BE:BE, 0.4)), IF(BE2 <= PERCENTILE(BE:BE, 0.8), 56 + (BE2 - PERCENTILE(BE:BE, 0.6)) * (69 - 56) / (PERCENTILE(BE:BE, 0.8) - PERCENTILE(BE:BE, 0.6)), IF(BE2 <= PERCENTILE(BE:BE, 0.95), 69 + (BE2 - PERCENTILE(BE:BE, 0.8)) * (86 - 69) / (PERCENTILE(BE:BE, 0.95) - PERCENTILE(BE:BE, 0.8)), 86 + (BE2 - PERCENTILE(BE:BE, 0.95)) * (100 - 86) / (PERCENTILE(BE:BE, 1) - PERCENTILE(BE:BE, 0.95)) ))))))) -> 100 | BE2: =(BF2-AVERAGE(BF:BF))/STDEV(BF:BF) -> 1.2782488 | BF2: =IFERROR(AVERAGE(BG2:BJ2),"")*0.9+IFERROR(AVERAGE(BK2:BN2), 0)*0.1 -> 0.061139912 | BG2: -0.20065136 | BH2: -0.18072242 | BI2: 0.34369439 | BJ2: 0.26364685 | BK2: -0.18214161 | BL2: 0.91545821 | BM2: -0.17910011 | BN2: -0.14232711 | BO2: =IF(BP2 <= PERCENTILE(BP:BP, 0.1), 25 + (BP2 - MIN(BP:BP)) * (34 - 25) / (PERCENTILE(BP:BP, 0.1) - MIN(BP:BP)), IF(BP2 <= PERCENTILE(BP:BP, 0.2), 34 + (BP2 - PERCENTILE(BP:BP, 0.1)) * (41 - 34) / (PERCENTILE(BP:BP, 0.2) - PERCENTILE(BP:BP, 0.1)), IF(BP2 <= PERCENTILE(BP:BP, 0.35), 41 + (BP2 - PERCENTILE(BP:BP, 0.2)) * (49 - 41) / (PERCENTILE(BP:BP, 0.35) - PERCENTILE(BP:BP, 0.2)), IF(BP2 <= PERCENTILE(BP:BP, 0.55), 49 + (BP2 - PERCENTILE(BP:BP, 0.35)) * (58 - 49) / (PERCENTILE(BP:BP, 0.55) - PERCENTILE(BP:BP, 0.35)), IF(BP2 <= PERCENTILE(BP:BP, 0.75), 58 + (BP2 - PERCENTILE(BP:BP, 0.55)) * (67 - 58) / (PERCENTILE(BP:BP, 0.75) - PERCENTILE(BP:BP, 0.55)), IF(BP2 <= PERCENTILE(BP:BP, 0.88), 67 + (BP2 - PERCENTILE(BP:BP, 0.75)) * (78 - 67) / (PERCENTILE(BP:BP, 0.88) - PERCENTILE(BP:BP, 0.75)), IF(BP2 <= PERCENTILE(BP:BP, 0.96), 78 + (BP2 - PERCENTILE(BP:BP, 0.88)) * (88 - 78) / (PERCENTILE(BP:BP, 0.96) - PERCENTILE(BP:BP, 0.88)), 88 + (BP2 - PERCENTILE(BP:BP, 0.96)) * (100 - 88) / (PERCENTILE(BP:BP, 1) - PERCENTILE(BP:BP, 0.96)) ))))))) -> 57.973775 | BP2: =(BQ2-AVERAGE(BQ:BQ))/STDEV(BQ:BQ) -> 0.47528595 | BQ2: =BR2*0.3+BS2*0.3+BT2*0.3+IFERROR(AVERAGE(BU2:BX2)*0.1, 0) -> 0.0086255249 | BR2: -0.19134729 | BS2: -0.17153482 | BT2: 0.26364685 | BU2: 0.028676406 | BV2: 1.8285951 | BW2: -0.17910011 | BX2: -0.14232711 | BY2: =IF(BZ2 <= PERCENTILE(BZ:BZ, 0.1), 25 + (BZ2 - MIN(BZ:BZ)) * (29 - 25) / (PERCENTILE(BZ:BZ, 0.1) - MIN(BZ:BZ)), IF(BZ2 <= PERCENTILE(BZ:BZ, 0.2), 29 + (BZ2 - PERCENTILE(BZ:BZ, 0.1)) * (36 - 29) / (PERCENTILE(BZ:BZ, 0.2) - PERCENTILE(BZ:BZ, 0.1)), IF(BZ2 <= PERCENTILE(BZ:BZ, 0.3), 36 + (BZ2 - PERCENTILE(BZ:BZ, 0.2)) * (43 - 36) / (PERCENTILE(BZ:BZ, 0.3) - PERCENTILE(BZ:BZ, 0.2)), IF(BZ2 <= PERCENTILE(BZ:BZ, 0.4), 43 + (BZ2 - PERCENTILE(BZ:BZ, 0.3)) * (49 - 43) / (PERCENTILE(BZ:BZ, 0.4) - PERCENTILE(BZ:BZ, 0.3)), IF(BZ2 <= PERCENTILE(BZ:BZ, 0.5), 49 + (BZ2 - PERCENTILE(BZ:BZ, 0.4)) * (55 - 49) / (PERCENTILE(BZ:BZ, 0.5) - PERCENTILE(BZ:BZ, 0.4)), IF(BZ2 <= PERCENTILE(BZ:BZ, 0.6), 55 + (BZ2 - PERCENTILE(BZ:BZ, 0.5)) * (60 - 55) / (PERCENTILE(BZ:BZ, 0.6) - PERCENTILE(BZ:BZ, 0.5)), IF(BZ2 <= PERCENTILE(BZ:BZ, 0.7), 60 + (BZ2 - PERCENTILE(BZ:BZ, 0.6)) * (66 - 60) / (PERCENTILE(BZ:BZ, 0.7) - PERCENTILE(BZ:BZ, 0.6)), IF(BZ2 <= PERCENTILE(BZ:BZ, 0.8), 66 + (BZ2 - PERCENTILE(BZ:BZ, 0.7)) * (71 - 66) / (PERCENTILE(BZ:BZ, 0.8) - PERCENTILE(BZ:BZ, 0.7)), IF(BZ2 <= PERCENTILE(BZ:BZ, 0.9), 71 + (BZ2 - PERCENTILE(BZ:BZ, 0.8)) * (81 - 71) / (PERCENTILE(BZ:BZ, 0.9) - PERCENTILE(BZ:BZ, 0.8)), IF(BZ2 <= PERCENTILE(BZ:BZ, 0.95), 81 + (BZ2 - PERCENTILE(BZ:BZ, 0.9)) * (88 - 81) / (PERCENTILE(BZ:BZ, 0.95) - PERCENTILE(BZ:BZ, 0.9)), 88 + (BZ2 - PERCENTILE(BZ:BZ, 0.95)) * (100 - 88) / (PERCENTILE(BZ:BZ, 1) - PERCENTILE(BZ:BZ, 0.95)) )))))))))) -> 69.342134 | BZ2: =(CA2-MEDIAN(CA:CA))/STDEV(CA:CA) -> 0.89922645 | CA2: =IFERROR(AVERAGE(CB2:CF2)*0.9+AVERAGE(CG2:CI2)*0.1, -1) -> 0.4341758 | CB2: 0.91545821 | CC2: 1.8469334 | CD2: -0.18214161 | CE2: 0.26364685 | CF2: -0.14232711 | CG2: 0.35890909 | CH2: -2.1493834 | CI2: 0.22727195 | CJ2: =IF(CK2 <= PERCENTILE(CK:CK, 0.1), 25 + (CK2 - MIN(CK:CK)) * (40 - 25) / (PERCENTILE(CK:CK, 0.1) - MIN(CK:CK)), IF(CK2 <= PERCENTILE(CK:CK, 0.2), 40 + (CK2 - PERCENTILE(CK:CK, 0.1)) * (47 - 40) / (PERCENTILE(CK:CK, 0.2) - PERCENTILE(CK:CK, 0.1)), IF(CK2 <= PERCENTILE(CK:CK, 0.3), 47 + (CK2 - PERCENTILE(CK:CK, 0.2)) * (50 - 47) / (PERCENTILE(CK:CK, 0.3) - PERCENTILE(CK:CK, 0.2)), IF(CK2 <= PERCENTILE(CK:CK, 0.4), 50 + (CK2 - PERCENTILE(CK:CK, 0.3)) * (56 - 50) / (PERCENTILE(CK:CK, 0.4) - PERCENTILE(CK:CK, 0.3)), IF(CK2 <= PERCENTILE(CK:CK, 0.5), 56 + (CK2 - PERCENTILE(CK:CK, 0.4)) * (61 - 56) / (PERCENTILE(CK:CK, 0.5) - PERCENTILE(CK:CK, 0.4)), IF(CK2 <= PERCENTILE(CK:CK, 0.6), 61 + (CK2 - PERCENTILE(CK:CK, 0.5)) * (66 - 61) / (PERCENTILE(CK:CK, 0.6) - PERCENTILE(CK:CK, 0.5)), IF(CK2 <= PERCENTILE(CK:CK, 0.7), 66 + (CK2 - PERCENTILE(CK:CK, 0.6)) * (70 - 66) / (PERCENTILE(CK:CK, 0.7) - PERCENTILE(CK:CK, 0.6)), IF(CK2 <= PERCENTILE(CK:CK, 0.8), 70 + (CK2 - PERCENTILE(CK:CK, 0.7)) * (75 - 70) / (PERCENTILE(CK:CK, 0.8) - PERCENTILE(CK:CK, 0.7)), IF(CK2 <= PERCENTILE(CK:CK, 0.9), 75 + (CK2 - PERCENTILE(CK:CK, 0.8)) * (84 - 75) / (PERCENTILE(CK:CK, 0.9) - PERCENTILE(CK:CK, 0.8)), IF(CK2 <= PERCENTILE(CK:CK, 0.95), 84 + (CK2 - PERCENTILE(CK:CK, 0.9)) * (90 - 84) / (PERCENTILE(CK:CK, 0.95) - PERCENTILE(CK:CK, 0.9)), 90 + (CK2 - PERCENTILE(CK:CK, 0.95)) * (100 - 90) / (PERCENTILE(CK:CK, 1) - PERCENTILE(CK:CK, 0.95)) )))))))))) -> 48.018458 | CK2: =(CL2-MEDIAN(CL:CL))/STDEV(CL:CL) -> -0.75682726 | CL2: =IFERROR(AVERAGE(CM2:CS2)*0.85+IFERROR(AVERAGE(CT2:CU2), 0)*0.1+CV2*0.05,-1) -> -0.54511797 | CM2: -0.64966504 | CN2: -0.52025117 | CO2: -0.17917077 | CP2: -0.28076875 | CQ2: -0.7628479 | CR2: -0.66320138 | CS2: -0.85814246 | CT2: -0.90795915 | CU2: -0.71612828 | CV2: 0.22727195 | CW2: =IF(CX2 <= PERCENTILE(CX:CX, 0.1), 25 + (CX2 - MIN(CX:CX)) * (62 - 25) / (PERCENTILE(CX:CX, 0.1) - MIN(CX:CX)), IF(CX2 <= PERCENTILE(CX:CX, 0.2), 62 + (CX2 - PERCENTILE(CX:CX, 0.1)) * (70 - 62) / (PERCENTILE(CX:CX, 0.2) - PERCENTILE(CX:CX, 0.1)), IF(CX2 <= PERCENTILE(CX:CX, 0.3), 70 + (CX2 - PERCENTILE(CX:CX, 0.2)) * (75 - 70) / (PERCENTILE(CX:CX, 0.3) - PERCENTILE(CX:CX, 0.2)), IF(CX2 <= PERCENTILE(CX:CX, 0.4), 75 + (CX2 - PERCENTILE(CX:CX, 0.3)) * (78 - 75) / (PERCENTILE(CX:CX, 0.4) - PERCENTILE(CX:CX, 0.3)), IF(CX2 <= PERCENTILE(CX:CX, 0.5), 78 + (CX2 - PERCENTILE(CX:CX, 0.4)) * (80 - 78) / (PERCENTILE(CX:CX, 0.5) - PERCENTILE(CX:CX, 0.4)), IF(CX2 <= PERCENTILE(CX:CX, 0.6), 80 + (CX2 - PERCENTILE(CX:CX, 0.5)) * (83 - 80) / (PERCENTILE(CX:CX, 0.6) - PERCENTILE(CX:CX, 0.5)), IF(CX2 <= PERCENTILE(CX:CX, 0.7), 83 + (CX2 - PERCENTILE(CX:CX, 0.6)) * (85 - 83) / (PERCENTILE(CX:CX, 0.7) - PERCENTILE(CX:CX, 0.6)), IF(CX2 <= PERCENTILE(CX:CX, 0.8), 85 + (CX2 - PERCENTILE(CX:CX, 0.7)) * (90 - 85) / (PERCENTILE(CX:CX, 0.8) - PERCENTILE(CX:CX, 0.7)), IF(CX2 <= PERCENTILE(CX:CX, 0.88), 90 + (CX2 - PERCENTILE(CX:CX, 0.8)) * (95 - 90) / (PERCENTILE(CX:CX, 0.88) - PERCENTILE(CX:CX, 0.8)), IF(CX2 <= PERCENTILE(CX:CX, 0.94), 95 + (CX2 - PERCENTILE(CX:CX, 0.88)) * (98 - 95) / (PERCENTILE(CX:CX, 0.94) - PERCENTILE(CX:CX, 0.88)), IF(CX2 <= PERCENTILE(CX:CX, 0.98), 98, 98 + (CX2 - PERCENTILE(CX:CX, 0.98)) * (100 - 98) / (PERCENTILE(CX:CX, 1) - PERCENTILE(CX:CX, 0.98)) ))))))))))) -> 80 | CX2: =(CY2-MEDIAN(CY:CY))/STDEV(CY:CY) -> 0 | CY2: =IFERROR(AVERAGE(CZ2:DB2), -2) -> 0.42302324 | CZ2: -0.53695765 | DA2: 1.3418202 | DB2: 0.46420716
A3: 708 | B3: 2014-15 | C3: Kevin Garnett | D3: =IF(E3 <= PERCENTILE(E:E, 0.25), 25 + (E3 - MIN(E:E)) * (66 - 25) / (PERCENTILE(E:E, 0.25) - MIN(E:E)), IF(E3 <= PERCENTILE(E:E, 0.5), 66 + (E3 - PERCENTILE(E:E, 0.25)) * (73 - 66) / (PERCENTILE(E:E, 0.5) - PERCENTILE(E:E, 0.25)), IF(E3 <= PERCENTILE(E:E, 0.75), 73 + (E3 - PERCENTILE(E:E, 0.5)) * (80 - 73) / (PERCENTILE(E:E, 0.75) - PERCENTILE(E:E, 0.5)), IF(E3 <= PERCENTILE(E:E, 0.85), 80 + (E3 - PERCENTILE(E:E, 0.75)) * (84.45 - 80) / (PERCENTILE(E:E, 0.85) - PERCENTILE(E:E, 0.75)), IF(E3 <= PERCENTILE(E:E, 0.92), 84.45 + (E3 - PERCENTILE(E:E, 0.85)) * (89 - 84.45) / (PERCENTILE(E:E, 0.92) - PERCENTILE(E:E, 0.85)), IF(E3 <= PERCENTILE(E:E, 0.96), 89 + (E3 - PERCENTILE(E:E, 0.92)) * (94 - 89) / (PERCENTILE(E:E, 0.96) - PERCENTILE(E:E, 0.92)), IF(E3 <= PERCENTILE(E:E, 0.99), 94 + (E3 - PERCENTILE(E:E, 0.96)) * (98 - 94) / (PERCENTILE(E:E, 0.99) - PERCENTILE(E:E, 0.96)), 98 + (E3 - PERCENTILE(E:E, 0.99)) * (100 - 98) / (PERCENTILE(E:E, 1) - PERCENTILE(E:E, 0.99)) ))))))) -> 73 | E3: =(F3-MEDIAN(F:F))/STDEV(F:F) -> 0 | F3: =iferror(if(ISBLANK(G3:Q3),-0.5,AVERAGE(G3:Q3))*0.8+iferror(AVERAGE(R3:U3, 0)*0.15, 0)+iferror(AVERAGE(V3:X3, 0)*0.5, 0), -1) -> -0.46489189 | G3: -0.9864258 | H3: -1.2085768 | I3: -1.0509722 | J3: -0.72519606 | K3: -0.95705144 | L3: -0.10183865 | M3: -0.10183865 | N3: -0.10183865 | O3: -0.22847268 | P3: -0.81314307 | Q3: -0.82146442 | R3: -1.2437634 | S3: 0.15671153 | T3: -0.40336846 | U3: -0.70529057 | V3: -0.3360142 | W3: 1.4547977 | X3: -0.18189001 | Y3: =IF(Z3 <= PERCENTILE(Z:Z, 0.25), 25 + (Z3 - MIN(Z:Z)) * (30 - 25) / (PERCENTILE(Z:Z, 0.25) - MIN(Z:Z)), IF(Z3 <= PERCENTILE(Z:Z, 0.4), 30 + (Z3 - PERCENTILE(Z:Z, 0.25)) * (40 - 30) / (PERCENTILE(Z:Z, 0.4) - PERCENTILE(Z:Z, 0.25)), IF(Z3 <= PERCENTILE(Z:Z, 0.55), 40 + (Z3 - PERCENTILE(Z:Z, 0.4)) * (50 - 40) / (PERCENTILE(Z:Z, 0.55) - PERCENTILE(Z:Z, 0.4)), IF(Z3 <= PERCENTILE(Z:Z, 0.7), 50 + (Z3 - PERCENTILE(Z:Z, 0.55)) * (65 - 50) / (PERCENTILE(Z:Z, 0.7) - PERCENTILE(Z:Z, 0.55)), IF(Z3 <= PERCENTILE(Z:Z, 0.85), 65 + (Z3 - PERCENTILE(Z:Z, 0.7)) * (80 - 65) / (PERCENTILE(Z:Z, 0.85) - PERCENTILE(Z:Z, 0.7)), IF(Z3 <= PERCENTILE(Z:Z, 0.95), 80 + (Z3 - PERCENTILE(Z:Z, 0.85)) * (90 - 80) / (PERCENTILE(Z:Z, 0.95) - PERCENTILE(Z:Z, 0.85)), IF(Z3 <= PERCENTILE(Z:Z, 0.99), 90 + (Z3 - PERCENTILE(Z:Z, 0.95)) * (96 - 90) / (PERCENTILE(Z:Z, 0.99) - PERCENTILE(Z:Z, 0.95)), 96 + (Z3 - PERCENTILE(Z:Z, 0.99)) * (100 - 96) / (PERCENTILE(Z:Z, 1) - PERCENTILE(Z:Z, 0.99)) ))))))) -> 67.684122 | Z3: =(AA3-MEDIAN(AA:AA))/STDEV(AA:AA) -> 0.61377712 | AA3: =IFERROR(AVERAGE(AB3:AD3)*0.7+AVERAGE(AE3:AL3)*0.25+AM3*0.05, -1) -> -0.33054433 | AB3: -0.41543679 | AC3: -0.38838591 | AG3: 0.11512386 | AH3: -1.3181872 | AI3: -0.21817449 | AJ3: -0.030423211 | AK3: -1.4365355 | AL3: 1.2898873 | AM3: 0.34779666 | AN3: =IF(AO3 <= PERCENTILE(AO:AO, 0.15), 25 + (AO3 - MIN(AO:AO)) * (41 - 25) / (PERCENTILE(AO:AO, 0.15) - MIN(AO:AO)), IF(AO3 <= PERCENTILE(AO:AO, 0.3), 41 + (AO3 - PERCENTILE(AO:AO, 0.15)) * (55 - 41) / (PERCENTILE(AO:AO, 0.3) - PERCENTILE(AO:AO, 0.15)), IF(AO3 <= PERCENTILE(AO:AO, 0.5), 55 + (AO3 - PERCENTILE(AO:AO, 0.3)) * (65 - 55) / (PERCENTILE(AO:AO, 0.5) - PERCENTILE(AO:AO, 0.3)), IF(AO3 <= PERCENTILE(AO:AO, 0.7), 65 + (AO3 - PERCENTILE(AO:AO, 0.5)) * (75 - 65) / (PERCENTILE(AO:AO, 0.7) - PERCENTILE(AO:AO, 0.5)), IF(AO3 <= PERCENTILE(AO:AO, 0.85), 75 + (AO3 - PERCENTILE(AO:AO, 0.7)) * (80 - 75) / (PERCENTILE(AO:AO, 0.85) - PERCENTILE(AO:AO, 0.7)), IF(AO3 <= PERCENTILE(AO:AO, 0.95), 80 + (AO3 - PERCENTILE(AO:AO, 0.85)) * (90 - 80) / (PERCENTILE(AO:AO, 0.95) - PERCENTILE(AO:AO, 0.85)), 90 + (AO3 - PERCENTILE(AO:AO, 0.95)) * (100 - 90) / (PERCENTILE(AO:AO, 1) - PERCENTILE(AO:AO, 0.95)) )))))) -> 48.356951 | AO3: =(AP3-MEDIAN(AP:AP))/STDEV(AP:AP) -> -1.2368385 | AP3: =IFERROR(AQ3*0.4+AVERAGE(AR3:AU3)*0.45+AVERAGE(AV3:BC3)*0.15, -1) -> -0.75522804 | AQ3: -0.59443757 | AR3: -0.54850115 | AS3: -1.2085768 | BB3: -0.80963423 | BC3: -0.81850527 | BD3: =IF(BE3 <= PERCENTILE(BE:BE, 0.05), 25 + (BE3 - MIN(BE:BE)) * (26 - 25) / (PERCENTILE(BE:BE, 0.05) - MIN(BE:BE)), IF(BE3 <= PERCENTILE(BE:BE, 0.15), 26 + (BE3 - PERCENTILE(BE:BE, 0.05)) * (28 - 26) / (PERCENTILE(BE:BE, 0.15) - PERCENTILE(BE:BE, 0.05)), IF(BE3 <= PERCENTILE(BE:BE, 0.25), 28 + (BE3 - PERCENTILE(BE:BE, 0.15)) * (35 - 28) / (PERCENTILE(BE:BE, 0.25) - PERCENTILE(BE:BE, 0.15)), IF(BE3 <= PERCENTILE(BE:BE, 0.4), 35 + (BE3 - PERCENTILE(BE:BE, 0.25)) * (44 - 35) / (PERCENTILE(BE:BE, 0.4) - PERCENTILE(BE:BE, 0.25)), IF(BE3 <= PERCENTILE(BE:BE, 0.6), 44 + (BE3 - PERCENTILE(BE:BE, 0.4)) * (56 - 44) / (PERCENTILE(BE:BE, 0.6) - PERCENTILE(BE:BE, 0.4)), IF(BE3 <= PERCENTILE(BE:BE, 0.8), 56 + (BE3 - PERCENTILE(BE:BE, 0.6)) * (69 - 56) / (PERCENTILE(BE:BE, 0.8) - PERCENTILE(BE:BE, 0.6)), IF(BE3 <= PERCENTILE(BE:BE, 0.95), 69 + (BE3 - PERCENTILE(BE:BE, 0.8)) * (86 - 69) / (PERCENTILE(BE:BE, 0.95) - PERCENTILE(BE:BE, 0.8)), 86 + (BE3 - PERCENTILE(BE:BE, 0.95)) * (100 - 86) / (PERCENTILE(BE:BE, 1) - PERCENTILE(BE:BE, 0.95)) ))))))) -> 25 | BE3: =(BF3-AVERAGE(BF:BF))/STDEV(BF:BF) -> -1.12449 | BF3: =IFERROR(AVERAGE(BG3:BJ3),"")*0.9+IFERROR(AVERAGE(BK3:BN3), 0)*0.1 -> -0.22471937 | BG3: -0.21802163 | BH3: -0.13529033 | BI3: 0.08462814 | BJ3: -0.49580012 | BK3: -1.1844828 | BL3: 0.91545821 | BM3: -1.1666497 | BN3: -0.67274497 | BO3: =IF(BP3 <= PERCENTILE(BP:BP, 0.1), 25 + (BP3 - MIN(BP:BP)) * (34 - 25) / (PERCENTILE(BP:BP, 0.1) - MIN(BP:BP)), IF(BP3 <= PERCENTILE(BP:BP, 0.2), 34 + (BP3 - PERCENTILE(BP:BP, 0.1)) * (41 - 34) / (PERCENTILE(BP:BP, 0.2) - PERCENTILE(BP:BP, 0.1)), IF(BP3 <= PERCENTILE(BP:BP, 0.35), 41 + (BP3 - PERCENTILE(BP:BP, 0.2)) * (49 - 41) / (PERCENTILE(BP:BP, 0.35) - PERCENTILE(BP:BP, 0.2)), IF(BP3 <= PERCENTILE(BP:BP, 0.55), 49 + (BP3 - PERCENTILE(BP:BP, 0.35)) * (58 - 49) / (PERCENTILE(BP:BP, 0.55) - PERCENTILE(BP:BP, 0.35)), IF(BP3 <= PERCENTILE(BP:BP, 0.75), 58 + (BP3 - PERCENTILE(BP:BP, 0.55)) * (67 - 58) / (PERCENTILE(BP:BP, 0.75) - PERCENTILE(BP:BP, 0.55)), IF(BP3 <= PERCENTILE(BP:BP, 0.88), 67 + (BP3 - PERCENTILE(BP:BP, 0.75)) * (78 - 67) / (PERCENTILE(BP:BP, 0.88) - PERCENTILE(BP:BP, 0.75)), IF(BP3 <= PERCENTILE(BP:BP, 0.96), 78 + (BP3 - PERCENTILE(BP:BP, 0.88)) * (88 - 78) / (PERCENTILE(BP:BP, 0.96) - PERCENTILE(BP:BP, 0.88)), 88 + (BP3 - PERCENTILE(BP:BP, 0.96)) * (100 - 88) / (PERCENTILE(BP:BP, 1) - PERCENTILE(BP:BP, 0.96)) ))))))) -> 100 | BP3: =(BQ3-AVERAGE(BQ:BQ))/STDEV(BQ:BQ) -> 1.0737801 | BQ3: =BR3*0.3+BS3*0.3+BT3*0.3+IFERROR(AVERAGE(BU3:BX3)*0.1, 0) -> 0.10707831 | BR3: 0.27936357 | BS3: 0.52328023 | BT3: -0.49580012 | BU3: 0.36311886 | BV3: 2.0772839 | BW3: -1.1666497 | BX3: -0.67274497 | BY3: =IF(BZ3 <= PERCENTILE(BZ:BZ, 0.1), 25 + (BZ3 - MIN(BZ:BZ)) * (29 - 25) / (PERCENTILE(BZ:BZ, 0.1) - MIN(BZ:BZ)), IF(BZ3 <= PERCENTILE(BZ:BZ, 0.2), 29 + (BZ3 - PERCENTILE(BZ:BZ, 0.1)) * (36 - 29) / (PERCENTILE(BZ:BZ, 0.2) - PERCENTILE(BZ:BZ, 0.1)), IF(BZ3 <= PERCENTILE(BZ:BZ, 0.3), 36 + (BZ3 - PERCENTILE(BZ:BZ, 0.2)) * (43 - 36) / (PERCENTILE(BZ:BZ, 0.3) - PERCENTILE(BZ:BZ, 0.2)), IF(BZ3 <= PERCENTILE(BZ:BZ, 0.4), 43 + (BZ3 - PERCENTILE(BZ:BZ, 0.3)) * (49 - 43) / (PERCENTILE(BZ:BZ, 0.4) - PERCENTILE(BZ:BZ, 0.3)), IF(BZ3 <= PERCENTILE(BZ:BZ, 0.5), 49 + (BZ3 - PERCENTILE(BZ:BZ, 0.4)) * (55 - 49) / (PERCENTILE(BZ:BZ, 0.5) - PERCENTILE(BZ:BZ, 0.4)), IF(BZ3 <= PERCENTILE(BZ:BZ, 0.6), 55 + (BZ3 - PERCENTILE(BZ:BZ, 0.5)) * (60 - 55) / (PERCENTILE(BZ:BZ, 0.6) - PERCENTILE(BZ:BZ, 0.5)), IF(BZ3 <= PERCENTILE(BZ:BZ, 0.7), 60 + (BZ3 - PERCENTILE(BZ:BZ, 0.6)) * (66 - 60) / (PERCENTILE(BZ:BZ, 0.7) - PERCENTILE(BZ:BZ, 0.6)), IF(BZ3 <= PERCENTILE(BZ:BZ, 0.8), 66 + (BZ3 - PERCENTILE(BZ:BZ, 0.7)) * (71 - 66) / (PERCENTILE(BZ:BZ, 0.8) - PERCENTILE(BZ:BZ, 0.7)), IF(BZ3 <= PERCENTILE(BZ:BZ, 0.9), 71 + (BZ3 - PERCENTILE(BZ:BZ, 0.8)) * (81 - 71) / (PERCENTILE(BZ:BZ, 0.9) - PERCENTILE(BZ:BZ, 0.8)), IF(BZ3 <= PERCENTILE(BZ:BZ, 0.95), 81 + (BZ3 - PERCENTILE(BZ:BZ, 0.9)) * (88 - 81) / (PERCENTILE(BZ:BZ, 0.95) - PERCENTILE(BZ:BZ, 0.9)), 88 + (BZ3 - PERCENTILE(BZ:BZ, 0.95)) * (100 - 88) / (PERCENTILE(BZ:BZ, 1) - PERCENTILE(BZ:BZ, 0.95)) )))))))))) -> 55 | BZ3: =(CA3-MEDIAN(CA:CA))/STDEV(CA:CA) -> 0 | CA3: =IFERROR(AVERAGE(CB3:CF3)*0.9+AVERAGE(CG3:CI3)*0.1, -1) -> 0.089566651 | CB3: 0.91545821 | CC3: 2.0978857 | CD3: -1.1844828 | CE3: -0.49580012 | CF3: -0.67274497 | CG3: 0.47314014 | CH3: -1.9905242 | CI3: 0.63867678 | CJ3: =IF(CK3 <= PERCENTILE(CK:CK, 0.1), 25 + (CK3 - MIN(CK:CK)) * (40 - 25) / (PERCENTILE(CK:CK, 0.1) - MIN(CK:CK)), IF(CK3 <= PERCENTILE(CK:CK, 0.2), 40 + (CK3 - PERCENTILE(CK:CK, 0.1)) * (47 - 40) / (PERCENTILE(CK:CK, 0.2) - PERCENTILE(CK:CK, 0.1)), IF(CK3 <= PERCENTILE(CK:CK, 0.3), 47 + (CK3 - PERCENTILE(CK:CK, 0.2)) * (50 - 47) / (PERCENTILE(CK:CK, 0.3) - PERCENTILE(CK:CK, 0.2)), IF(CK3 <= PERCENTILE(CK:CK, 0.4), 50 + (CK3 - PERCENTILE(CK:CK, 0.3)) * (56 - 50) / (PERCENTILE(CK:CK, 0.4) - PERCENTILE(CK:CK, 0.3)), IF(CK3 <= PERCENTILE(CK:CK, 0.5), 56 + (CK3 - PERCENTILE(CK:CK, 0.4)) * (61 - 56) / (PERCENTILE(CK:CK, 0.5) - PERCENTILE(CK:CK, 0.4)), IF(CK3 <= PERCENTILE(CK:CK, 0.6), 61 + (CK3 - PERCENTILE(CK:CK, 0.5)) * (66 - 61) / (PERCENTILE(CK:CK, 0.6) - PERCENTILE(CK:CK, 0.5)), IF(CK3 <= PERCENTILE(CK:CK, 0.7), 66 + (CK3 - PERCENTILE(CK:CK, 0.6)) * (70 - 66) / (PERCENTILE(CK:CK, 0.7) - PERCENTILE(CK:CK, 0.6)), IF(CK3 <= PERCENTILE(CK:CK, 0.8), 70 + (CK3 - PERCENTILE(CK:CK, 0.7)) * (75 - 70) / (PERCENTILE(CK:CK, 0.8) - PERCENTILE(CK:CK, 0.7)), IF(CK3 <= PERCENTILE(CK:CK, 0.9), 75 + (CK3 - PERCENTILE(CK:CK, 0.8)) * (84 - 75) / (PERCENTILE(CK:CK, 0.9) - PERCENTILE(CK:CK, 0.8)), IF(CK3 <= PERCENTILE(CK:CK, 0.95), 84 + (CK3 - PERCENTILE(CK:CK, 0.9)) * (90 - 84) / (PERCENTILE(CK:CK, 0.95) - PERCENTILE(CK:CK, 0.9)), 90 + (CK3 - PERCENTILE(CK:CK, 0.95)) * (100 - 90) / (PERCENTILE(CK:CK, 1) - PERCENTILE(CK:CK, 0.95)) )))))))))) -> 73.216344 | CK3: =(CL3-MEDIAN(CL:CL))/STDEV(CL:CL) -> 0.78708943 | CL3: =IFERROR(AVERAGE(CM3:CS3)*0.85+IFERROR(AVERAGE(CT3:CU3), 0)*0.1+CV3*0.05,-1) -> -0.29370139 | CM3: -0.57668765 | CN3: -0.46116913 | CO3: -0.17917077 | CP3: -0.28913651 | CQ3: -0.8758079 | CR3: 0.1487329 | CS3: -0.7543033 | CT3: 1.4588838 | CU3: -0.71612828 | CV3: 0.63867678 | CW3: =IF(CX3 <= PERCENTILE(CX:CX, 0.1), 25 + (CX3 - MIN(CX:CX)) * (62 - 25) / (PERCENTILE(CX:CX, 0.1) - MIN(CX:CX)), IF(CX3 <= PERCENTILE(CX:CX, 0.2), 62 + (CX3 - PERCENTILE(CX:CX, 0.1)) * (70 - 62) / (PERCENTILE(CX:CX, 0.2) - PERCENTILE(CX:CX, 0.1)), IF(CX3 <= PERCENTILE(CX:CX, 0.3), 70 + (CX3 - PERCENTILE(CX:CX, 0.2)) * (75 - 70) / (PERCENTILE(CX:CX, 0.3) - PERCENTILE(CX:CX, 0.2)), IF(CX3 <= PERCENTILE(CX:CX, 0.4), 75 + (CX3 - PERCENTILE(CX:CX, 0.3)) * (78 - 75) / (PERCENTILE(CX:CX, 0.4) - PERCENTILE(CX:CX, 0.3)), IF(CX3 <= PERCENTILE(CX:CX, 0.5), 78 + (CX3 - PERCENTILE(CX:CX, 0.4)) * (80 - 78) / (PERCENTILE(CX:CX, 0.5) - PERCENTILE(CX:CX, 0.4)), IF(CX3 <= PERCENTILE(CX:CX, 0.6), 80 + (CX3 - PERCENTILE(CX:CX, 0.5)) * (83 - 80) / (PERCENTILE(CX:CX, 0.6) - PERCENTILE(CX:CX, 0.5)), IF(CX3 <= PERCENTILE(CX:CX, 0.7), 83 + (CX3 - PERCENTILE(CX:CX, 0.6)) * (85 - 83) / (PERCENTILE(CX:CX, 0.7) - PERCENTILE(CX:CX, 0.6)), IF(CX3 <= PERCENTILE(CX:CX, 0.8), 85 + (CX3 - PERCENTILE(CX:CX, 0.7)) * (90 - 85) / (PERCENTILE(CX:CX, 0.8) - PERCENTILE(CX:CX, 0.7)), IF(CX3 <= PERCENTILE(CX:CX, 0.88), 90 + (CX3 - PERCENTILE(CX:CX, 0.8)) * (95 - 90) / (PERCENTILE(CX:CX, 0.88) - PERCENTILE(CX:CX, 0.8)), IF(CX3 <= PERCENTILE(CX:CX, 0.94), 95 + (CX3 - PERCENTILE(CX:CX, 0.88)) * (98 - 95) / (PERCENTILE(CX:CX, 0.94) - PERCENTILE(CX:CX, 0.88)), IF(CX3 <= PERCENTILE(CX:CX, 0.98), 98, 98 + (CX3 - PERCENTILE(CX:CX, 0.98)) * (100 - 98) / (PERCENTILE(CX:CX, 1) - PERCENTILE(CX:CX, 0.98)) ))))))))))) -> 86.322552 | CX3: =(CY3-MEDIAN(CY:CY))/STDEV(CY:CY) -> 0.48179951 | CY3: =IFERROR(AVERAGE(CZ3:DB3), -2) -> 0.77271196 | CZ3: 0.40983502 | DA3: 1.4343567 | DB3: 0.47394414
A4: 708 | B4: 2015-16 | C4: Kevin Garnett | D4: =IF(E4 <= PERCENTILE(E:E, 0.25), 25 + (E4 - MIN(E:E)) * (66 - 25) / (PERCENTILE(E:E, 0.25) - MIN(E:E)), IF(E4 <= PERCENTILE(E:E, 0.5), 66 + (E4 - PERCENTILE(E:E, 0.25)) * (73 - 66) / (PERCENTILE(E:E, 0.5) - PERCENTILE(E:E, 0.25)), IF(E4 <= PERCENTILE(E:E, 0.75), 73 + (E4 - PERCENTILE(E:E, 0.5)) * (80 - 73) / (PERCENTILE(E:E, 0.75) - PERCENTILE(E:E, 0.5)), IF(E4 <= PERCENTILE(E:E, 0.85), 80 + (E4 - PERCENTILE(E:E, 0.75)) * (84.45 - 80) / (PERCENTILE(E:E, 0.85) - PERCENTILE(E:E, 0.75)), IF(E4 <= PERCENTILE(E:E, 0.92), 84.45 + (E4 - PERCENTILE(E:E, 0.85)) * (89 - 84.45) / (PERCENTILE(E:E, 0.92) - PERCENTILE(E:E, 0.85)), IF(E4 <= PERCENTILE(E:E, 0.96), 89 + (E4 - PERCENTILE(E:E, 0.92)) * (94 - 89) / (PERCENTILE(E:E, 0.96) - PERCENTILE(E:E, 0.92)), IF(E4 <= PERCENTILE(E:E, 0.99), 94 + (E4 - PERCENTILE(E:E, 0.96)) * (98 - 94) / (PERCENTILE(E:E, 0.99) - PERCENTILE(E:E, 0.96)), 98 + (E4 - PERCENTILE(E:E, 0.99)) * (100 - 98) / (PERCENTILE(E:E, 1) - PERCENTILE(E:E, 0.99)) ))))))) -> 66 | E4: =(F4-MEDIAN(F:F))/STDEV(F:F) -> -0.9491766 | F4: =iferror(if(ISBLANK(G4:Q4),-0.5,AVERAGE(G4:Q4))*0.8+iferror(AVERAGE(R4:U4, 0)*0.15, 0)+iferror(AVERAGE(V4:X4, 0)*0.5, 0), -1) -> -0.75019653 | G4: -0.8707894 | H4: -1.8903773 | I4: -1.1154105 | J4: -0.21384747 | K4: -0.025050693 | L4: -0.59543011 | M4: -0.59543011 | N4: -0.59543011 | O4: -0.91962268 | P4: -0.86527377 | Q4: -0.82146442 | R4: -0.5583575 | S4: -0.29514234 | T4: -0.56420842 | U4: -0.95489837 | V4: 0.18829226 | W4: -0.91312151 | X4: 0.24286529 | Y4: =IF(Z4 <= PERCENTILE(Z:Z, 0.25), 25 + (Z4 - MIN(Z:Z)) * (30 - 25) / (PERCENTILE(Z:Z, 0.25) - MIN(Z:Z)), IF(Z4 <= PERCENTILE(Z:Z, 0.4), 30 + (Z4 - PERCENTILE(Z:Z, 0.25)) * (40 - 30) / (PERCENTILE(Z:Z, 0.4) - PERCENTILE(Z:Z, 0.25)), IF(Z4 <= PERCENTILE(Z:Z, 0.55), 40 + (Z4 - PERCENTILE(Z:Z, 0.4)) * (50 - 40) / (PERCENTILE(Z:Z, 0.55) - PERCENTILE(Z:Z, 0.4)), IF(Z4 <= PERCENTILE(Z:Z, 0.7), 50 + (Z4 - PERCENTILE(Z:Z, 0.55)) * (65 - 50) / (PERCENTILE(Z:Z, 0.7) - PERCENTILE(Z:Z, 0.55)), IF(Z4 <= PERCENTILE(Z:Z, 0.85), 65 + (Z4 - PERCENTILE(Z:Z, 0.7)) * (80 - 65) / (PERCENTILE(Z:Z, 0.85) - PERCENTILE(Z:Z, 0.7)), IF(Z4 <= PERCENTILE(Z:Z, 0.95), 80 + (Z4 - PERCENTILE(Z:Z, 0.85)) * (90 - 80) / (PERCENTILE(Z:Z, 0.95) - PERCENTILE(Z:Z, 0.85)), IF(Z4 <= PERCENTILE(Z:Z, 0.99), 90 + (Z4 - PERCENTILE(Z:Z, 0.95)) * (96 - 90) / (PERCENTILE(Z:Z, 0.99) - PERCENTILE(Z:Z, 0.95)), 96 + (Z4 - PERCENTILE(Z:Z, 0.99)) * (100 - 96) / (PERCENTILE(Z:Z, 1) - PERCENTILE(Z:Z, 0.99)) ))))))) -> 30 | Z4: =(AA4-MEDIAN(AA:AA))/STDEV(AA:AA) -> -0.063214793 | AA4: =IFERROR(AVERAGE(AB4:AD4)*0.7+AVERAGE(AE4:AL4)*0.25+AM4*0.05, -1) -> -0.49553255 | AB4: -0.5765656 | AC4: -0.50472102 | AG4: -0.65144842 | AH4: 0.044527929 | AI4: -0.77077919 | AJ4: -0.5158737 | AK4: -0.997177 | AL4: 1.2898873 | AM4: -1.0075921 | AN4: =IF(AO4 <= PERCENTILE(AO:AO, 0.15), 25 + (AO4 - MIN(AO:AO)) * (41 - 25) / (PERCENTILE(AO:AO, 0.15) - MIN(AO:AO)), IF(AO4 <= PERCENTILE(AO:AO, 0.3), 41 + (AO4 - PERCENTILE(AO:AO, 0.15)) * (55 - 41) / (PERCENTILE(AO:AO, 0.3) - PERCENTILE(AO:AO, 0.15)), IF(AO4 <= PERCENTILE(AO:AO, 0.5), 55 + (AO4 - PERCENTILE(AO:AO, 0.3)) * (65 - 55) / (PERCENTILE(AO:AO, 0.5) - PERCENTILE(AO:AO, 0.3)), IF(AO4 <= PERCENTILE(AO:AO, 0.7), 65 + (AO4 - PERCENTILE(AO:AO, 0.5)) * (75 - 65) / (PERCENTILE(AO:AO, 0.7) - PERCENTILE(AO:AO, 0.5)), IF(AO4 <= PERCENTILE(AO:AO, 0.85), 75 + (AO4 - PERCENTILE(AO:AO, 0.7)) * (80 - 75) / (PERCENTILE(AO:AO, 0.85) - PERCENTILE(AO:AO, 0.7)), IF(AO4 <= PERCENTILE(AO:AO, 0.95), 80 + (AO4 - PERCENTILE(AO:AO, 0.85)) * (90 - 80) / (PERCENTILE(AO:AO, 0.95) - PERCENTILE(AO:AO, 0.85)), 90 + (AO4 - PERCENTILE(AO:AO, 0.95)) * (100 - 90) / (PERCENTILE(AO:AO, 1) - PERCENTILE(AO:AO, 0.95)) )))))) -> 25 | AO4: =(AP4-MEDIAN(AP:AP))/STDEV(AP:AP) -> -1.9217167 | AP4: =IFERROR(AQ4*0.4+AVERAGE(AR4:AU4)*0.45+AVERAGE(AV4:BC4)*0.15, -1) -> -0.95658419 | AQ4: -0.66677961 | AR4: -0.61562421 | AS4: -1.8903773 | BB4: -0.86178815 | BC4: -0.81850527 | BD4: =IF(BE4 <= PERCENTILE(BE:BE, 0.05), 25 + (BE4 - MIN(BE:BE)) * (26 - 25) / (PERCENTILE(BE:BE, 0.05) - MIN(BE:BE)), IF(BE4 <= PERCENTILE(BE:BE, 0.15), 26 + (BE4 - PERCENTILE(BE:BE, 0.05)) * (28 - 26) / (PERCENTILE(BE:BE, 0.15) - PERCENTILE(BE:BE, 0.05)), IF(BE4 <= PERCENTILE(BE:BE, 0.25), 28 + (BE4 - PERCENTILE(BE:BE, 0.15)) * (35 - 28) / (PERCENTILE(BE:BE, 0.25) - PERCENTILE(BE:BE, 0.15)), IF(BE4 <= PERCENTILE(BE:BE, 0.4), 35 + (BE4 - PERCENTILE(BE:BE, 0.25)) * (44 - 35) / (PERCENTILE(BE:BE, 0.4) - PERCENTILE(BE:BE, 0.25)), IF(BE4 <= PERCENTILE(BE:BE, 0.6), 44 + (BE4 - PERCENTILE(BE:BE, 0.4)) * (56 - 44) / (PERCENTILE(BE:BE, 0.6) - PERCENTILE(BE:BE, 0.4)), IF(BE4 <= PERCENTILE(BE:BE, 0.8), 56 + (BE4 - PERCENTILE(BE:BE, 0.6)) * (69 - 56) / (PERCENTILE(BE:BE, 0.8) - PERCENTILE(BE:BE, 0.6)), IF(BE4 <= PERCENTILE(BE:BE, 0.95), 69 + (BE4 - PERCENTILE(BE:BE, 0.8)) * (86 - 69) / (PERCENTILE(BE:BE, 0.95) - PERCENTILE(BE:BE, 0.8)), 86 + (BE4 - PERCENTILE(BE:BE, 0.95)) * (100 - 86) / (PERCENTILE(BE:BE, 1) - PERCENTILE(BE:BE, 0.95)) ))))))) -> 55.296413 | BE4: =(BF4-AVERAGE(BF:BF))/STDEV(BF:BF) -> 0.33648395 | BF4: =IFERROR(AVERAGE(BG4:BJ4),"")*0.9+IFERROR(AVERAGE(BK4:BN4), 0)*0.1 -> -0.050903992 | BG4: -0.35698386 | BH4: -0.36754366 | BI4: 0.43004981 | BJ4: -0.10724586 | BK4: 0.59745708 | BL4: 0.13741514 | BM4: 0.58899401 | BN4: 0.25548628 | BO4: =IF(BP4 <= PERCENTILE(BP:BP, 0.1), 25 + (BP4 - MIN(BP:BP)) * (34 - 25) / (PERCENTILE(BP:BP, 0.1) - MIN(BP:BP)), IF(BP4 <= PERCENTILE(BP:BP, 0.2), 34 + (BP4 - PERCENTILE(BP:BP, 0.1)) * (41 - 34) / (PERCENTILE(BP:BP, 0.2) - PERCENTILE(BP:BP, 0.1)), IF(BP4 <= PERCENTILE(BP:BP, 0.35), 41 + (BP4 - PERCENTILE(BP:BP, 0.2)) * (49 - 41) / (PERCENTILE(BP:BP, 0.35) - PERCENTILE(BP:BP, 0.2)), IF(BP4 <= PERCENTILE(BP:BP, 0.55), 49 + (BP4 - PERCENTILE(BP:BP, 0.35)) * (58 - 49) / (PERCENTILE(BP:BP, 0.55) - PERCENTILE(BP:BP, 0.35)), IF(BP4 <= PERCENTILE(BP:BP, 0.75), 58 + (BP4 - PERCENTILE(BP:BP, 0.55)) * (67 - 58) / (PERCENTILE(BP:BP, 0.75) - PERCENTILE(BP:BP, 0.55)), IF(BP4 <= PERCENTILE(BP:BP, 0.88), 67 + (BP4 - PERCENTILE(BP:BP, 0.75)) * (78 - 67) / (PERCENTILE(BP:BP, 0.88) - PERCENTILE(BP:BP, 0.75)), IF(BP4 <= PERCENTILE(BP:BP, 0.96), 78 + (BP4 - PERCENTILE(BP:BP, 0.88)) * (88 - 78) / (PERCENTILE(BP:BP, 0.96) - PERCENTILE(BP:BP, 0.88)), 88 + (BP4 - PERCENTILE(BP:BP, 0.96)) * (100 - 88) / (PERCENTILE(BP:BP, 1) - PERCENTILE(BP:BP, 0.96)) ))))))) -> 43.13613 | BP4: =(BQ4-AVERAGE(BQ:BQ))/STDEV(BQ:BQ) -> -0.61851394 | BQ4: =BR4*0.3+BS4*0.3+BT4*0.3+IFERROR(AVERAGE(BU4:BX4)*0.1, 0) -> -0.17130547 | BR4: -0.37963164 | BS4: -0.34872586 | BT4: -0.10724586 | BU4: -0.13854482 | BV4: 2.4690862 | BW4: 0.58899401 | BX4: 0.25548628 | BY4: =IF(BZ4 <= PERCENTILE(BZ:BZ, 0.1), 25 + (BZ4 - MIN(BZ:BZ)) * (29 - 25) / (PERCENTILE(BZ:BZ, 0.1) - MIN(BZ:BZ)), IF(BZ4 <= PERCENTILE(BZ:BZ, 0.2), 29 + (BZ4 - PERCENTILE(BZ:BZ, 0.1)) * (36 - 29) / (PERCENTILE(BZ:BZ, 0.2) - PERCENTILE(BZ:BZ, 0.1)), IF(BZ4 <= PERCENTILE(BZ:BZ, 0.3), 36 + (BZ4 - PERCENTILE(BZ:BZ, 0.2)) * (43 - 36) / (PERCENTILE(BZ:BZ, 0.3) - PERCENTILE(BZ:BZ, 0.2)), IF(BZ4 <= PERCENTILE(BZ:BZ, 0.4), 43 + (BZ4 - PERCENTILE(BZ:BZ, 0.3)) * (49 - 43) / (PERCENTILE(BZ:BZ, 0.4) - PERCENTILE(BZ:BZ, 0.3)), IF(BZ4 <= PERCENTILE(BZ:BZ, 0.5), 49 + (BZ4 - PERCENTILE(BZ:BZ, 0.4)) * (55 - 49) / (PERCENTILE(BZ:BZ, 0.5) - PERCENTILE(BZ:BZ, 0.4)), IF(BZ4 <= PERCENTILE(BZ:BZ, 0.6), 55 + (BZ4 - PERCENTILE(BZ:BZ, 0.5)) * (60 - 55) / (PERCENTILE(BZ:BZ, 0.6) - PERCENTILE(BZ:BZ, 0.5)), IF(BZ4 <= PERCENTILE(BZ:BZ, 0.7), 60 + (BZ4 - PERCENTILE(BZ:BZ, 0.6)) * (66 - 60) / (PERCENTILE(BZ:BZ, 0.7) - PERCENTILE(BZ:BZ, 0.6)), IF(BZ4 <= PERCENTILE(BZ:BZ, 0.8), 66 + (BZ4 - PERCENTILE(BZ:BZ, 0.7)) * (71 - 66) / (PERCENTILE(BZ:BZ, 0.8) - PERCENTILE(BZ:BZ, 0.7)), IF(BZ4 <= PERCENTILE(BZ:BZ, 0.9), 71 + (BZ4 - PERCENTILE(BZ:BZ, 0.8)) * (81 - 71) / (PERCENTILE(BZ:BZ, 0.9) - PERCENTILE(BZ:BZ, 0.8)), IF(BZ4 <= PERCENTILE(BZ:BZ, 0.95), 81 + (BZ4 - PERCENTILE(BZ:BZ, 0.9)) * (88 - 81) / (PERCENTILE(BZ:BZ, 0.95) - PERCENTILE(BZ:BZ, 0.9)), 88 + (BZ4 - PERCENTILE(BZ:BZ, 0.95)) * (100 - 88) / (PERCENTILE(BZ:BZ, 1) - PERCENTILE(BZ:BZ, 0.95)) )))))))))) -> 100 | BZ4: =(CA4-MEDIAN(CA:CA))/STDEV(CA:CA) -> 1.3452879 | CA4: =IFERROR(AVERAGE(CB4:CF4)*0.9+AVERAGE(CG4:CI4)*0.1, -1) -> 0.60511923 | CB4: 0.13741514 | CC4: 2.4932541 | CD4: 0.59745708 | CE4: -0.10724586 | CF4: 0.25548628 | CG4: 0.65056284 | CH4: -1.2756574 | CI4: 0.54629113 | CJ4: =IF(CK4 <= PERCENTILE(CK:CK, 0.1), 25 + (CK4 - MIN(CK:CK)) * (40 - 25) / (PERCENTILE(CK:CK, 0.1) - MIN(CK:CK)), IF(CK4 <= PERCENTILE(CK:CK, 0.2), 40 + (CK4 - PERCENTILE(CK:CK, 0.1)) * (47 - 40) / (PERCENTILE(CK:CK, 0.2) - PERCENTILE(CK:CK, 0.1)), IF(CK4 <= PERCENTILE(CK:CK, 0.3), 47 + (CK4 - PERCENTILE(CK:CK, 0.2)) * (50 - 47) / (PERCENTILE(CK:CK, 0.3) - PERCENTILE(CK:CK, 0.2)), IF(CK4 <= PERCENTILE(CK:CK, 0.4), 50 + (CK4 - PERCENTILE(CK:CK, 0.3)) * (56 - 50) / (PERCENTILE(CK:CK, 0.4) - PERCENTILE(CK:CK, 0.3)), IF(CK4 <= PERCENTILE(CK:CK, 0.5), 56 + (CK4 - PERCENTILE(CK:CK, 0.4)) * (61 - 56) / (PERCENTILE(CK:CK, 0.5) - PERCENTILE(CK:CK, 0.4)), IF(CK4 <= PERCENTILE(CK:CK, 0.6), 61 + (CK4 - PERCENTILE(CK:CK, 0.5)) * (66 - 61) / (PERCENTILE(CK:CK, 0.6) - PERCENTILE(CK:CK, 0.5)), IF(CK4 <= PERCENTILE(CK:CK, 0.7), 66 + (CK4 - PERCENTILE(CK:CK, 0.6)) * (70 - 66) / (PERCENTILE(CK:CK, 0.7) - PERCENTILE(CK:CK, 0.6)), IF(CK4 <= PERCENTILE(CK:CK, 0.8), 70 + (CK4 - PERCENTILE(CK:CK, 0.7)) * (75 - 70) / (PERCENTILE(CK:CK, 0.8) - PERCENTILE(CK:CK, 0.7)), IF(CK4 <= PERCENTILE(CK:CK, 0.9), 75 + (CK4 - PERCENTILE(CK:CK, 0.8)) * (84 - 75) / (PERCENTILE(CK:CK, 0.9) - PERCENTILE(CK:CK, 0.8)), IF(CK4 <= PERCENTILE(CK:CK, 0.95), 84 + (CK4 - PERCENTILE(CK:CK, 0.9)) * (90 - 84) / (PERCENTILE(CK:CK, 0.95) - PERCENTILE(CK:CK, 0.9)), 90 + (CK4 - PERCENTILE(CK:CK, 0.95)) * (100 - 90) / (PERCENTILE(CK:CK, 1) - PERCENTILE(CK:CK, 0.95)) )))))))))) -> 25 | CK4: =(CL4-MEDIAN(CL:CL))/STDEV(CL:CL) -> -1.1458158 | CL4: =IFERROR(AVERAGE(CM4:CS4)*0.85+IFERROR(AVERAGE(CT4:CU4), 0)*0.1+CV4*0.05,-1) -> -0.60846216 | CM4: -0.75913113 | CN4: -0.6974973 | CO4: -0.59155389 | CP4: -0.72425998 | CQ4: -1.1582079 | CR4: 0.27364586 | CS4: -0.91006205 | CT4: -0.90795915 | CU4: -0.71612828 | CV4: 0.54629113 | CW4: =IF(CX4 <= PERCENTILE(CX:CX, 0.1), 25 + (CX4 - MIN(CX:CX)) * (62 - 25) / (PERCENTILE(CX:CX, 0.1) - MIN(CX:CX)), IF(CX4 <= PERCENTILE(CX:CX, 0.2), 62 + (CX4 - PERCENTILE(CX:CX, 0.1)) * (70 - 62) / (PERCENTILE(CX:CX, 0.2) - PERCENTILE(CX:CX, 0.1)), IF(CX4 <= PERCENTILE(CX:CX, 0.3), 70 + (CX4 - PERCENTILE(CX:CX, 0.2)) * (75 - 70) / (PERCENTILE(CX:CX, 0.3) - PERCENTILE(CX:CX, 0.2)), IF(CX4 <= PERCENTILE(CX:CX, 0.4), 75 + (CX4 - PERCENTILE(CX:CX, 0.3)) * (78 - 75) / (PERCENTILE(CX:CX, 0.4) - PERCENTILE(CX:CX, 0.3)), IF(CX4 <= PERCENTILE(CX:CX, 0.5), 78 + (CX4 - PERCENTILE(CX:CX, 0.4)) * (80 - 78) / (PERCENTILE(CX:CX, 0.5) - PERCENTILE(CX:CX, 0.4)), IF(CX4 <= PERCENTILE(CX:CX, 0.6), 80 + (CX4 - PERCENTILE(CX:CX, 0.5)) * (83 - 80) / (PERCENTILE(CX:CX, 0.6) - PERCENTILE(CX:CX, 0.5)), IF(CX4 <= PERCENTILE(CX:CX, 0.7), 83 + (CX4 - PERCENTILE(CX:CX, 0.6)) * (85 - 83) / (PERCENTILE(CX:CX, 0.7) - PERCENTILE(CX:CX, 0.6)), IF(CX4 <= PERCENTILE(CX:CX, 0.8), 85 + (CX4 - PERCENTILE(CX:CX, 0.7)) * (90 - 85) / (PERCENTILE(CX:CX, 0.8) - PERCENTILE(CX:CX, 0.7)), IF(CX4 <= PERCENTILE(CX:CX, 0.88), 90 + (CX4 - PERCENTILE(CX:CX, 0.8)) * (95 - 90) / (PERCENTILE(CX:CX, 0.88) - PERCENTILE(CX:CX, 0.8)), IF(CX4 <= PERCENTILE(CX:CX, 0.94), 95 + (CX4 - PERCENTILE(CX:CX, 0.88)) * (98 - 95) / (PERCENTILE(CX:CX, 0.94) - PERCENTILE(CX:CX, 0.88)), IF(CX4 <= PERCENTILE(CX:CX, 0.98), 98, 98 + (CX4 - PERCENTILE(CX:CX, 0.98)) * (100 - 98) / (PERCENTILE(CX:CX, 1) - PERCENTILE(CX:CX, 0.98)) ))))))))))) -> 74.074014 | CX4: =(CY4-MEDIAN(CY:CY))/STDEV(CY:CY) -> -0.16041995 | CY4: =IFERROR(AVERAGE(CZ4:DB4), -2) -> 0.30659089 | CZ4: -0.13457077 | DA4: 1.198697 | DB4: -0.1443536
A5: 951 | B5: 2013-14 | C5: Ray Allen | D5: =IF(E5 <= PERCENTILE(E:E, 0.25), 25 + (E5 - MIN(E:E)) * (66 - 25) / (PERCENTILE(E:E, 0.25) - MIN(E:E)), IF(E5 <= PERCENTILE(E:E, 0.5), 66 + (E5 - PERCENTILE(E:E, 0.25)) * (73 - 66) / (PERCENTILE(E:E, 0.5) - PERCENTILE(E:E, 0.25)), IF(E5 <= PERCENTILE(E:E, 0.75), 73 + (E5 - PERCENTILE(E:E, 0.5)) * (80 - 73) / (PERCENTILE(E:E, 0.75) - PERCENTILE(E:E, 0.5)), IF(E5 <= PERCENTILE(E:E, 0.85), 80 + (E5 - PERCENTILE(E:E, 0.75)) * (84.45 - 80) / (PERCENTILE(E:E, 0.85) - PERCENTILE(E:E, 0.75)), IF(E5 <= PERCENTILE(E:E, 0.92), 84.45 + (E5 - PERCENTILE(E:E, 0.85)) * (89 - 84.45) / (PERCENTILE(E:E, 0.92) - PERCENTILE(E:E, 0.85)), IF(E5 <= PERCENTILE(E:E, 0.96), 89 + (E5 - PERCENTILE(E:E, 0.92)) * (94 - 89) / (PERCENTILE(E:E, 0.96) - PERCENTILE(E:E, 0.92)), IF(E5 <= PERCENTILE(E:E, 0.99), 94 + (E5 - PERCENTILE(E:E, 0.96)) * (98 - 94) / (PERCENTILE(E:E, 0.99) - PERCENTILE(E:E, 0.96)), 98 + (E5 - PERCENTILE(E:E, 0.99)) * (100 - 98) / (PERCENTILE(E:E, 1) - PERCENTILE(E:E, 0.99)) ))))))) -> 80 | E5: =(F5-MEDIAN(F:F))/STDEV(F:F) -> 0.76635298 | F5: =iferror(if(ISBLANK(G5:Q5),-0.5,AVERAGE(G5:Q5))*0.8+iferror(AVERAGE(R5:U5, 0)*0.15, 0)+iferror(AVERAGE(V5:X5, 0)*0.5, 0), -1) -> -0.23454059 | G5: -0.72046208 | H5: -0.3904163 | I5: -0.030352525 | J5: -0.61672818 | K5: -0.51435108 | L5: 0.14495707 | M5: 0.14495707 | N5: 0.14495707 | O5: -0.25320569 | P5: 0.073078706 | Q5: 0.0029180465 | R5: -0.61805414 | S5: -0.021131829 | T5: -0.026934516 | U5: -0.53888537 | V5: 0.028492515 | W5: -0.58603294 | X5: 0.14257584 | Y5: =IF(Z5 <= PERCENTILE(Z:Z, 0.25), 25 + (Z5 - MIN(Z:Z)) * (30 - 25) / (PERCENTILE(Z:Z, 0.25) - MIN(Z:Z)), IF(Z5 <= PERCENTILE(Z:Z, 0.4), 30 + (Z5 - PERCENTILE(Z:Z, 0.25)) * (40 - 30) / (PERCENTILE(Z:Z, 0.4) - PERCENTILE(Z:Z, 0.25)), IF(Z5 <= PERCENTILE(Z:Z, 0.55), 40 + (Z5 - PERCENTILE(Z:Z, 0.4)) * (50 - 40) / (PERCENTILE(Z:Z, 0.55) - PERCENTILE(Z:Z, 0.4)), IF(Z5 <= PERCENTILE(Z:Z, 0.7), 50 + (Z5 - PERCENTILE(Z:Z, 0.55)) * (65 - 50) / (PERCENTILE(Z:Z, 0.7) - PERCENTILE(Z:Z, 0.55)), IF(Z5 <= PERCENTILE(Z:Z, 0.85), 65 + (Z5 - PERCENTILE(Z:Z, 0.7)) * (80 - 65) / (PERCENTILE(Z:Z, 0.85) - PERCENTILE(Z:Z, 0.7)), IF(Z5 <= PERCENTILE(Z:Z, 0.95), 80 + (Z5 - PERCENTILE(Z:Z, 0.85)) * (90 - 80) / (PERCENTILE(Z:Z, 0.95) - PERCENTILE(Z:Z, 0.85)), IF(Z5 <= PERCENTILE(Z:Z, 0.99), 90 + (Z5 - PERCENTILE(Z:Z, 0.95)) * (96 - 90) / (PERCENTILE(Z:Z, 0.99) - PERCENTILE(Z:Z, 0.95)), 96 + (Z5 - PERCENTILE(Z:Z, 0.99)) * (100 - 96) / (PERCENTILE(Z:Z, 1) - PERCENTILE(Z:Z, 0.99)) ))))))) -> 41.708031 | Z5: =(AA5-MEDIAN(AA:AA))/STDEV(AA:AA) -> 0 | AA5: =IFERROR(AVERAGE(AB5:AD5)*0.7+AVERAGE(AE5:AL5)*0.25+AM5*0.05, -1) -> -0.48012661 | AB5: -0.47282514 | AC5: -0.38838591 | AG5: -0.65144842 | AH5: 0.044527929 | AI5: -0.86100036 | AJ5: -0.66413589 | AK5: -0.4532093 | AL5: -0.49448933 | AM5: -1.0075921 | AN5: =IF(AO5 <= PERCENTILE(AO:AO, 0.15), 25 + (AO5 - MIN(AO:AO)) * (41 - 25) / (PERCENTILE(AO:AO, 0.15) - MIN(AO:AO)), IF(AO5 <= PERCENTILE(AO:AO, 0.3), 41 + (AO5 - PERCENTILE(AO:AO, 0.15)) * (55 - 41) / (PERCENTILE(AO:AO, 0.3) - PERCENTILE(AO:AO, 0.15)), IF(AO5 <= PERCENTILE(AO:AO, 0.5), 55 + (AO5 - PERCENTILE(AO:AO, 0.3)) * (65 - 55) / (PERCENTILE(AO:AO, 0.5) - PERCENTILE(AO:AO, 0.3)), IF(AO5 <= PERCENTILE(AO:AO, 0.7), 65 + (AO5 - PERCENTILE(AO:AO, 0.5)) * (75 - 65) / (PERCENTILE(AO:AO, 0.7) - PERCENTILE(AO:AO, 0.5)), IF(AO5 <= PERCENTILE(AO:AO, 0.85), 75 + (AO5 - PERCENTILE(AO:AO, 0.7)) * (80 - 75) / (PERCENTILE(AO:AO, 0.85) - PERCENTILE(AO:AO, 0.7)), IF(AO5 <= PERCENTILE(AO:AO, 0.95), 80 + (AO5 - PERCENTILE(AO:AO, 0.85)) * (90 - 80) / (PERCENTILE(AO:AO, 0.95) - PERCENTILE(AO:AO, 0.85)), 90 + (AO5 - PERCENTILE(AO:AO, 0.95)) * (100 - 90) / (PERCENTILE(AO:AO, 1) - PERCENTILE(AO:AO, 0.95)) )))))) -> 76.084604 | AO5: =(AP5-MEDIAN(AP:AP))/STDEV(AP:AP) -> 0.13728435 | AP5: =IFERROR(AQ5*0.4+AVERAGE(AR5:AU5)*0.45+AVERAGE(AV5:BC5)*0.15, -1) -> -0.35123199 | AQ5: -0.47886799 | AR5: -0.34713198 | AS5: -0.3904163 | BB5: 0.076982458 | BC5: 0.006531764 | BD5: =IF(BE5 <= PERCENTILE(BE:BE, 0.05), 25 + (BE5 - MIN(BE:BE)) * (26 - 25) / (PERCENTILE(BE:BE, 0.05) - MIN(BE:BE)), IF(BE5 <= PERCENTILE(BE:BE, 0.15), 26 + (BE5 - PERCENTILE(BE:BE, 0.05)) * (28 - 26) / (PERCENTILE(BE:BE, 0.15) - PERCENTILE(BE:BE, 0.05)), IF(BE5 <= PERCENTILE(BE:BE, 0.25), 28 + (BE5 - PERCENTILE(BE:BE, 0.15)) * (35 - 28) / (PERCENTILE(BE:BE, 0.25) - PERCENTILE(BE:BE, 0.15)), IF(BE5 <= PERCENTILE(BE:BE, 0.4), 35 + (BE5 - PERCENTILE(BE:BE, 0.25)) * (44 - 35) / (PERCENTILE(BE:BE, 0.4) - PERCENTILE(BE:BE, 0.25)), IF(BE5 <= PERCENTILE(BE:BE, 0.6), 44 + (BE5 - PERCENTILE(BE:BE, 0.4)) * (56 - 44) / (PERCENTILE(BE:BE, 0.6) - PERCENTILE(BE:BE, 0.4)), IF(BE5 <= PERCENTILE(BE:BE, 0.8), 56 + (BE5 - PERCENTILE(BE:BE, 0.6)) * (69 - 56) / (PERCENTILE(BE:BE, 0.8) - PERCENTILE(BE:BE, 0.6)), IF(BE5 <= PERCENTILE(BE:BE, 0.95), 69 + (BE5 - PERCENTILE(BE:BE, 0.8)) * (86 - 69) / (PERCENTILE(BE:BE, 0.95) - PERCENTILE(BE:BE, 0.8)), 86 + (BE5 - PERCENTILE(BE:BE, 0.95)) * (100 - 86) / (PERCENTILE(BE:BE, 1) - PERCENTILE(BE:BE, 0.95)) ))))))) -> 35 | BE5: =(BF5-AVERAGE(BF:BF))/STDEV(BF:BF) -> -0.90398853 | BF5: =IFERROR(AVERAGE(BG5:BJ5),"")*0.9+IFERROR(AVERAGE(BK5:BN5), 0)*0.1 -> -0.19848581 | BG5: -0.33961359 | BH5: -0.38319873 | BI5: 0.24006789 | BJ5: -0.37216922 | BK5: 0.040600873 | BL5: -0.31644331 | BM5: 0.04035535 | BN5: -0.0097226455 | BO5: =IF(BP5 <= PERCENTILE(BP:BP, 0.1), 25 + (BP5 - MIN(BP:BP)) * (34 - 25) / (PERCENTILE(BP:BP, 0.1) - MIN(BP:BP)), IF(BP5 <= PERCENTILE(BP:BP, 0.2), 34 + (BP5 - PERCENTILE(BP:BP, 0.1)) * (41 - 34) / (PERCENTILE(BP:BP, 0.2) - PERCENTILE(BP:BP, 0.1)), IF(BP5 <= PERCENTILE(BP:BP, 0.35), 41 + (BP5 - PERCENTILE(BP:BP, 0.2)) * (49 - 41) / (PERCENTILE(BP:BP, 0.35) - PERCENTILE(BP:BP, 0.2)), IF(BP5 <= PERCENTILE(BP:BP, 0.55), 49 + (BP5 - PERCENTILE(BP:BP, 0.35)) * (58 - 49) / (PERCENTILE(BP:BP, 0.55) - PERCENTILE(BP:BP, 0.35)), IF(BP5 <= PERCENTILE(BP:BP, 0.75), 58 + (BP5 - PERCENTILE(BP:BP, 0.55)) * (67 - 58) / (PERCENTILE(BP:BP, 0.75) - PERCENTILE(BP:BP, 0.55)), IF(BP5 <= PERCENTILE(BP:BP, 0.88), 67 + (BP5 - PERCENTILE(BP:BP, 0.75)) * (78 - 67) / (PERCENTILE(BP:BP, 0.88) - PERCENTILE(BP:BP, 0.75)), IF(BP5 <= PERCENTILE(BP:BP, 0.96), 78 + (BP5 - PERCENTILE(BP:BP, 0.88)) * (88 - 78) / (PERCENTILE(BP:BP, 0.96) - PERCENTILE(BP:BP, 0.88)), 88 + (BP5 - PERCENTILE(BP:BP, 0.96)) * (100 - 88) / (PERCENTILE(BP:BP, 1) - PERCENTILE(BP:BP, 0.96)) ))))))) -> 25 | BP5: =(BQ5-AVERAGE(BQ:BQ))/STDEV(BQ:BQ) -> -1.4154277 | BQ5: =BR5*0.3+BS5*0.3+BT5*0.3+IFERROR(AVERAGE(BU5:BX5)*0.1, 0) -> -0.30239845 | BR5: -0.28548947 | BS5: -0.34217222 | BT5: -0.37216922 | BU5: 0.36311886 | BV5: -0.49171873 | BW5: 0.04035535 | BX5: -0.0097226455 | BY5: =IF(BZ5 <= PERCENTILE(BZ:BZ, 0.1), 25 + (BZ5 - MIN(BZ:BZ)) * (29 - 25) / (PERCENTILE(BZ:BZ, 0.1) - MIN(BZ:BZ)), IF(BZ5 <= PERCENTILE(BZ:BZ, 0.2), 29 + (BZ5 - PERCENTILE(BZ:BZ, 0.1)) * (36 - 29) / (PERCENTILE(BZ:BZ, 0.2) - PERCENTILE(BZ:BZ, 0.1)), IF(BZ5 <= PERCENTILE(BZ:BZ, 0.3), 36 + (BZ5 - PERCENTILE(BZ:BZ, 0.2)) * (43 - 36) / (PERCENTILE(BZ:BZ, 0.3) - PERCENTILE(BZ:BZ, 0.2)), IF(BZ5 <= PERCENTILE(BZ:BZ, 0.4), 43 + (BZ5 - PERCENTILE(BZ:BZ, 0.3)) * (49 - 43) / (PERCENTILE(BZ:BZ, 0.4) - PERCENTILE(BZ:BZ, 0.3)), IF(BZ5 <= PERCENTILE(BZ:BZ, 0.5), 49 + (BZ5 - PERCENTILE(BZ:BZ, 0.4)) * (55 - 49) / (PERCENTILE(BZ:BZ, 0.5) - PERCENTILE(BZ:BZ, 0.4)), IF(BZ5 <= PERCENTILE(BZ:BZ, 0.6), 55 + (BZ5 - PERCENTILE(BZ:BZ, 0.5)) * (60 - 55) / (PERCENTILE(BZ:BZ, 0.6) - PERCENTILE(BZ:BZ, 0.5)), IF(BZ5 <= PERCENTILE(BZ:BZ, 0.7), 60 + (BZ5 - PERCENTILE(BZ:BZ, 0.6)) * (66 - 60) / (PERCENTILE(BZ:BZ, 0.7) - PERCENTILE(BZ:BZ, 0.6)), IF(BZ5 <= PERCENTILE(BZ:BZ, 0.8), 66 + (BZ5 - PERCENTILE(BZ:BZ, 0.7)) * (71 - 66) / (PERCENTILE(BZ:BZ, 0.8) - PERCENTILE(BZ:BZ, 0.7)), IF(BZ5 <= PERCENTILE(BZ:BZ, 0.9), 71 + (BZ5 - PERCENTILE(BZ:BZ, 0.8)) * (81 - 71) / (PERCENTILE(BZ:BZ, 0.9) - PERCENTILE(BZ:BZ, 0.8)), IF(BZ5 <= PERCENTILE(BZ:BZ, 0.95), 81 + (BZ5 - PERCENTILE(BZ:BZ, 0.9)) * (88 - 81) / (PERCENTILE(BZ:BZ, 0.95) - PERCENTILE(BZ:BZ, 0.9)), 88 + (BZ5 - PERCENTILE(BZ:BZ, 0.95)) * (100 - 88) / (PERCENTILE(BZ:BZ, 1) - PERCENTILE(BZ:BZ, 0.95)) )))))))))) -> 36.892939 | BZ5: =(CA5-MEDIAN(CA:CA))/STDEV(CA:CA) -> -0.78947329 | CA5: =IFERROR(AVERAGE(CB5:CF5)*0.9+AVERAGE(CG5:CI5)*0.1, -1) -> -0.21298197 | CB5: -0.31644331 | CC5: -0.49449953 | CD5: 0.040600873 | CE5: -0.37216922 | CF5: -0.0097226455 | CG5: 0.10614251 | CH5: 0.29024131 | CI5: -0.56378012 | CJ5: =IF(CK5 <= PERCENTILE(CK:CK, 0.1), 25 + (CK5 - MIN(CK:CK)) * (40 - 25) / (PERCENTILE(CK:CK, 0.1) - MIN(CK:CK)), IF(CK5 <= PERCENTILE(CK:CK, 0.2), 40 + (CK5 - PERCENTILE(CK:CK, 0.1)) * (47 - 40) / (PERCENTILE(CK:CK, 0.2) - PERCENTILE(CK:CK, 0.1)), IF(CK5 <= PERCENTILE(CK:CK, 0.3), 47 + (CK5 - PERCENTILE(CK:CK, 0.2)) * (50 - 47) / (PERCENTILE(CK:CK, 0.3) - PERCENTILE(CK:CK, 0.2)), IF(CK5 <= PERCENTILE(CK:CK, 0.4), 50 + (CK5 - PERCENTILE(CK:CK, 0.3)) * (56 - 50) / (PERCENTILE(CK:CK, 0.4) - PERCENTILE(CK:CK, 0.3)), IF(CK5 <= PERCENTILE(CK:CK, 0.5), 56 + (CK5 - PERCENTILE(CK:CK, 0.4)) * (61 - 56) / (PERCENTILE(CK:CK, 0.5) - PERCENTILE(CK:CK, 0.4)), IF(CK5 <= PERCENTILE(CK:CK, 0.6), 61 + (CK5 - PERCENTILE(CK:CK, 0.5)) * (66 - 61) / (PERCENTILE(CK:CK, 0.6) - PERCENTILE(CK:CK, 0.5)), IF(CK5 <= PERCENTILE(CK:CK, 0.7), 66 + (CK5 - PERCENTILE(CK:CK, 0.6)) * (70 - 66) / (PERCENTILE(CK:CK, 0.7) - PERCENTILE(CK:CK, 0.6)), IF(CK5 <= PERCENTILE(CK:CK, 0.8), 70 + (CK5 - PERCENTILE(CK:CK, 0.7)) * (75 - 70) / (PERCENTILE(CK:CK, 0.8) - PERCENTILE(CK:CK, 0.7)), IF(CK5 <= PERCENTILE(CK:CK, 0.9), 75 + (CK5 - PERCENTILE(CK:CK, 0.8)) * (84 - 75) / (PERCENTILE(CK:CK, 0.9) - PERCENTILE(CK:CK, 0.8)), IF(CK5 <= PERCENTILE(CK:CK, 0.95), 84 + (CK5 - PERCENTILE(CK:CK, 0.9)) * (90 - 84) / (PERCENTILE(CK:CK, 0.95) - PERCENTILE(CK:CK, 0.9)), 90 + (CK5 - PERCENTILE(CK:CK, 0.95)) * (100 - 90) / (PERCENTILE(CK:CK, 1) - PERCENTILE(CK:CK, 0.95)) )))))))))) -> 61 | CK5: =(CL5-MEDIAN(CL:CL))/STDEV(CL:CL) -> 0 | CL5: =IFERROR(AVERAGE(CM5:CS5)*0.85+IFERROR(AVERAGE(CT5:CU5), 0)*0.1+CV5*0.05,-1) -> -0.42187367 | CM5: -0.32126677 | CN5: -0.10667686 | CO5: -0.51300472 | CP5: -0.69915671 | CQ5: -1.1299679 | CR5: 0.33610235 | CS5: -0.48172548 | CT5: -0.58101924 | CU5: -0.21169783 | CV5: -0.56378012 | CW5: =IF(CX5 <= PERCENTILE(CX:CX, 0.1), 25 + (CX5 - MIN(CX:CX)) * (62 - 25) / (PERCENTILE(CX:CX, 0.1) - MIN(CX:CX)), IF(CX5 <= PERCENTILE(CX:CX, 0.2), 62 + (CX5 - PERCENTILE(CX:CX, 0.1)) * (70 - 62) / (PERCENTILE(CX:CX, 0.2) - PERCENTILE(CX:CX, 0.1)), IF(CX5 <= PERCENTILE(CX:CX, 0.3), 70 + (CX5 - PERCENTILE(CX:CX, 0.2)) * (75 - 70) / (PERCENTILE(CX:CX, 0.3) - PERCENTILE(CX:CX, 0.2)), IF(CX5 <= PERCENTILE(CX:CX, 0.4), 75 + (CX5 - PERCENTILE(CX:CX, 0.3)) * (78 - 75) / (PERCENTILE(CX:CX, 0.4) - PERCENTILE(CX:CX, 0.3)), IF(CX5 <= PERCENTILE(CX:CX, 0.5), 78 + (CX5 - PERCENTILE(CX:CX, 0.4)) * (80 - 78) / (PERCENTILE(CX:CX, 0.5) - PERCENTILE(CX:CX, 0.4)), IF(CX5 <= PERCENTILE(CX:CX, 0.6), 80 + (CX5 - PERCENTILE(CX:CX, 0.5)) * (83 - 80) / (PERCENTILE(CX:CX, 0.6) - PERCENTILE(CX:CX, 0.5)), IF(CX5 <= PERCENTILE(CX:CX, 0.7), 83 + (CX5 - PERCENTILE(CX:CX, 0.6)) * (85 - 83) / (PERCENTILE(CX:CX, 0.7) - PERCENTILE(CX:CX, 0.6)), IF(CX5 <= PERCENTILE(CX:CX, 0.8), 85 + (CX5 - PERCENTILE(CX:CX, 0.7)) * (90 - 85) / (PERCENTILE(CX:CX, 0.8) - PERCENTILE(CX:CX, 0.7)), IF(CX5 <= PERCENTILE(CX:CX, 0.88), 90 + (CX5 - PERCENTILE(CX:CX, 0.8)) * (95 - 90) / (PERCENTILE(CX:CX, 0.88) - PERCENTILE(CX:CX, 0.8)), IF(CX5 <= PERCENTILE(CX:CX, 0.94), 95 + (CX5 - PERCENTILE(CX:CX, 0.88)) * (98 - 95) / (PERCENTILE(CX:CX, 0.94) - PERCENTILE(CX:CX, 0.88)), IF(CX5 <= PERCENTILE(CX:CX, 0.98), 98, 98 + (CX5 - PERCENTILE(CX:CX, 0.98)) * (100 - 98) / (PERCENTILE(CX:CX, 1) - PERCENTILE(CX:CX, 0.98)) ))))))))))) -> 25 | CX5: =(CY5-MEDIAN(CY:CY))/STDEV(CY:CY) -> -0.8662115 | CY5: =IFERROR(AVERAGE(CZ5:DB5), -2) -> -0.20567063 | CZ5: 0.090292494 | DA5: -0.67979446 | DB5: -0.027509931
